Workbook

Sheet Times
A1: Time | B1: Data | C1: Competição | D1: Adversário | E1: Mando | F1: Gols Pró | G1: Gols Contra | H1: xG Pró | I1: xG Contra | J1: Escanteios Pró | K1: Escanteios Contra | L1: Cartões Pró | M1: Cartões Contra | N1: Chutes Pró | O1: Chutes Contra | P1: Chutes Gol Pró | Q1: Chutes Gol Contra | R1: Posse Pró | S1: Faltas Time | T1: Faltas Adv | U1: Gols 1T Time | V1: Gols 1T Adv | W1: BTTS | X1: Saldo | Y1: Resultado | Z1: Favoritismo (preencher depois) | AA1: Estilo do Adversário (preencher depois) | AB1: Bloco Baixo (1-5) (preencher depois) | AC1: Pressão Alta (1-5) (preencher depois) | AD1: Transição Rápida (1-5) (preencher depois) | AE1: Posse/Dominância (1-5) (preencher depois) | AF1: Bola Parada/Físico (1-5) (preencher depois) | AG1: Aderência ao alvo (%) | AH1: Aderência Favoritismo | AI1: Peso | AK1: Peso Final
W2: =IF(AND(F2>1,G2>1),"Sim","Não") -> Não | X2: =F2-G2 -> 0 | Y2: =IF(F2>G2,"V",IF(F2=G2,"E","D")) -> E | AG2: =1-(ABS(AB2-INDEX('Jogos do Dia'!$G$2:$G$5,MATCH($A2,'Jogos do Dia'!$B$2:$B$5,0)))+ABS(AC2-INDEX('Jogos do Dia'!$H$2:$H$5,MATCH($A2,'Jogos do Dia'!$B$2:$B$5,0)))+ABS(AD2-INDEX('Jogos do Dia'!$I$2:$I$5,MATCH($A2,'Jogos do Dia'!$B$2:$B$5,0)))+ABS(AE2-INDEX('Jogos do Dia'!$J$2:$J$5,MATCH($A2,'Jogos do Dia'!$B$2:$B$5,0)))+ABS(AF2-INDEX('Jogos do Dia'!$K$2:$K$5,MATCH($A2,'Jogos do Dia'!$B$2:$B$5,0))))/20 -> #N/A | AH2: =1-ABS(Z2-INDEX('Jogos do Dia'!$F$2:$F$5,MATCH($A2,'Jogos do Dia'!$B$2:$B$5,0))) -> #N/A | AI2: =IF((INDEX('Jogos do Dia'!$A$2:$A$5,MATCH($A2,'Jogos do Dia'!$B$2:$B$5,0))-B2)<=10,100%,IF((INDEX('Jogos do Dia'!$A$2:$A$5,MATCH($A2,'Jogos do Dia'!$B$2:$B$5,0))-B2)<=20,85%,IF((INDEX('Jogos do Dia'!$A$2:$A$5,MATCH($A2,'Jogos do Dia'!$B$2:$B$5,0))-B2)<=30,70%,IF((INDEX('Jogos do Dia'!$A$2:$A$5,MATCH($A2,'Jogos do Dia'!$B$2:$B$5,0))-B2)<=45,50%,IF((INDEX('Jogos do Dia'!$A$2:$A$5,MATCH($A2,'Jogos do Dia'!$B$2:$B$5,0))-B2)<=90,30%,IF((INDEX('Jogos do Dia'!$A$2:$A$5,MATCH($A2,'Jogos do Dia'!$B$2:$B$5,0))-B2)<=180,15%,0%)))))) -> #N/A | AK2: =AG2*AH2*AI2 -> #N/A
W3: =IF(AND(F3>1,G3>1),"Sim","Não") -> Não | X3: =F3-G3 -> 0 | Y3: =IF(F3>G3,"V",IF(F3=G3,"E","D")) -> E | AG3: =1-(ABS(AB3-INDEX('Jogos do Dia'!$G$2:$G$5,MATCH($A3,'Jogos do Dia'!$B$2:$B$5,0)))+ABS(AC3-INDEX('Jogos do Dia'!$H$2:$H$5,MATCH($A3,'Jogos do Dia'!$B$2:$B$5,0)))+ABS(AD3-INDEX('Jogos do Dia'!$I$2:$I$5,MATCH($A3,'Jogos do Dia'!$B$2:$B$5,0)))+ABS(AE3-INDEX('Jogos do Dia'!$J$2:$J$5,MATCH($A3,'Jogos do Dia'!$B$2:$B$5,0)))+ABS(AF3-INDEX('Jogos do Dia'!$K$2:$K$5,MATCH($A3,'Jogos do Dia'!$B$2:$B$5,0))))/20 -> #N/A | AH3: =1-ABS(Z3-INDEX('Jogos do Dia'!$F$2:$F$5,MATCH($A3,'Jogos do Dia'!$B$2:$B$5,0))) -> #N/A | AI3: =IF((INDEX('Jogos do Dia'!$A$2:$A$5,MATCH($A3,'Jogos do Dia'!$B$2:$B$5,0))-B3)<=10,100%,IF((INDEX('Jogos do Dia'!$A$2:$A$5,MATCH($A3,'Jogos do Dia'!$B$2:$B$5,0))-B3)<=20,85%,IF((INDEX('Jogos do Dia'!$A$2:$A$5,MATCH($A3,'Jogos do Dia'!$B$2:$B$5,0))-B3)<=30,70%,IF((INDEX('Jogos do Dia'!$A$2:$A$5,MATCH($A3,'Jogos do Dia'!$B$2:$B$5,0))-B3)<=45,50%,IF((INDEX('Jogos do Dia'!$A$2:$A$5,MATCH($A3,'Jogos do Dia'!$B$2:$B$5,0))-B3)<=90,30%,IF((INDEX('Jogos do Dia'!$A$2:$A$5,MATCH($A3,'Jogos do Dia'!$B$2:$B$5,0))-B3)<=180,15%,0%)))))) -> #N/A | AK3: =AG3*AH3*AI3 -> #N/A
W4: =IF(AND(F4>1,G4>1),"Sim","Não") -> Não | X4: =F4-G4 -> 0 | Y4: =IF(F4>G4,"V",IF(F4=G4,"E","D")) -> E | AG4: =1-(ABS(AB4-INDEX('Jogos do Dia'!$G$2:$G$5,MATCH($A4,'Jogos do Dia'!$B$2:$B$5,0)))+ABS(AC4-INDEX('Jogos do Dia'!$H$2:$H$5,MATCH($A4,'Jogos do Dia'!$B$2:$B$5,0)))+ABS(AD4-INDEX('Jogos do Dia'!$I$2:$I$5,MATCH($A4,'Jogos do Dia'!$B$2:$B$5,0)))+ABS(AE4-INDEX('Jogos do Dia'!$J$2:$J$5,MATCH($A4,'Jogos do Dia'!$B$2:$B$5,0)))+ABS(AF4-INDEX('Jogos do Dia'!$K$2:$K$5,MATCH($A4,'Jogos do Dia'!$B$2:$B$5,0))))/20 -> #N/A | AH4: =1-ABS(Z4-INDEX('Jogos do Dia'!$F$2:$F$5,MATCH($A4,'Jogos do Dia'!$B$2:$B$5,0))) -> #N/A | AI4: =IF((INDEX('Jogos do Dia'!$A$2:$A$5,MATCH($A4,'Jogos do Dia'!$B$2:$B$5,0))-B4)<=10,100%,IF((INDEX('Jogos do Dia'!$A$2:$A$5,MATCH($A4,'Jogos do Dia'!$B$2:$B$5,0))-B4)<=20,85%,IF((INDEX('Jogos do Dia'!$A$2:$A$5,MATCH($A4,'Jogos do Dia'!$B$2:$B$5,0))-B4)<=30,70%,IF((INDEX('Jogos do Dia'!$A$2:$A$5,MATCH($A4,'Jogos do Dia'!$B$2:$B$5,0))-B4)<=45,50%,IF((INDEX('Jogos do Dia'!$A$2:$A$5,MATCH($A4,'Jogos do Dia'!$B$2:$B$5,0))-B4)<=90,30%,IF((INDEX('Jogos do Dia'!$A$2:$A$5,MATCH($A4,'Jogos do Dia'!$B$2:$B$5,0))-B4)<=180,15%,0%)))))) -> #N/A | AK4: =AG4*AH4*AI4 -> #N/A
W5: =IF(AND(F5>1,G5>1),"Sim","Não") -> Não | X5: =F5-G5 -> 0 | Y5: =IF(F5>G5,"V",IF(F5=G5,"E","D")) -> E | AG5: =1-(ABS(AB5-INDEX('Jogos do Dia'!$G$2:$G$5,MATCH($A5,'Jogos do Dia'!$B$2:$B$5,0)))+ABS(AC5-INDEX('Jogos do Dia'!$H$2:$H$5,MATCH($A5,'Jogos do Dia'!$B$2:$B$5,0)))+ABS(AD5-INDEX('Jogos do Dia'!$I$2:$I$5,MATCH($A5,'Jogos do Dia'!$B$2:$B$5,0)))+ABS(AE5-INDEX('Jogos do Dia'!$J$2:$J$5,MATCH($A5,'Jogos do Dia'!$B$2:$B$5,0)))+ABS(AF5-INDEX('Jogos do Dia'!$K$2:$K$5,MATCH($A5,'Jogos do Dia'!$B$2:$B$5,0))))/20 -> #N/A | AH5: =1-ABS(Z5-INDEX('Jogos do Dia'!$F$2:$F$5,MATCH($A5,'Jogos do Dia'!$B$2:$B$5,0))) -> #N/A | AI5: =IF((INDEX('Jogos do Dia'!$A$2:$A$5,MATCH($A5,'Jogos do Dia'!$B$2:$B$5,0))-B5)<=10,100%,IF((INDEX('Jogos do Dia'!$A$2:$A$5,MATCH($A5,'Jogos do Dia'!$B$2:$B$5,0))-B5)<=20,85%,IF((INDEX('Jogos do Dia'!$A$2:$A$5,MATCH($A5,'Jogos do Dia'!$B$2:$B$5,0))-B5)<=30,70%,IF((INDEX('Jogos do Dia'!$A$2:$A$5,MATCH($A5,'Jogos do Dia'!$B$2:$B$5,0))-B5)<=45,50%,IF((INDEX('Jogos do Dia'!$A$2:$A$5,MATCH($A5,'Jogos do Dia'!$B$2:$B$5,0))-B5)<=90,30%,IF((INDEX('Jogos do Dia'!$A$2:$A$5,MATCH($A5,'Jogos do Dia'!$B$2:$B$5,0))-B5)<=180,15%,0%)))))) -> #N/A | AK5: =AG5*AH5*AI5 -> #N/A
W6: =IF(AND(F6>1,G6>1),"Sim","Não") -> Não | X6: =F6-G6 -> 0 | Y6: =IF(F6>G6,"V",IF(F6=G6,"E","D")) -> E | AG6: =1-(ABS(AB6-INDEX('Jogos do Dia'!$G$2:$G$5,MATCH($A6,'Jogos do Dia'!$B$2:$B$5,0)))+ABS(AC6-INDEX('Jogos do Dia'!$H$2:$H$5,MATCH($A6,'Jogos do Dia'!$B$2:$B$5,0)))+ABS(AD6-INDEX('Jogos do Dia'!$I$2:$I$5,MATCH($A6,'Jogos do Dia'!$B$2:$B$5,0)))+ABS(AE6-INDEX('Jogos do Dia'!$J$2:$J$5,MATCH($A6,'Jogos do Dia'!$B$2:$B$5,0)))+ABS(AF6-INDEX('Jogos do Dia'!$K$2:$K$5,MATCH($A6,'Jogos do Dia'!$B$2:$B$5,0))))/20 -> #N/A | AH6: =1-ABS(Z6-INDEX('Jogos do Dia'!$F$2:$F$5,MATCH($A6,'Jogos do Dia'!$B$2:$B$5,0))) -> #N/A | AI6: =IF((INDEX('Jogos do Dia'!$A$2:$A$5,MATCH($A6,'Jogos do Dia'!$B$2:$B$5,0))-B6)<=10,100%,IF((INDEX('Jogos do Dia'!$A$2:$A$5,MATCH($A6,'Jogos do Dia'!$B$2:$B$5,0))-B6)<=20,85%,IF((INDEX('Jogos do Dia'!$A$2:$A$5,MATCH($A6,'Jogos do Dia'!$B$2:$B$5,0))-B6)<=30,70%,IF((INDEX('Jogos do Dia'!$A$2:$A$5,MATCH($A6,'Jogos do Dia'!$B$2:$B$5,0))-B6)<=45,50%,IF((INDEX('Jogos do Dia'!$A$2:$A$5,MATCH($A6,'Jogos do Dia'!$B$2:$B$5,0))-B6)<=90,30%,IF((INDEX('Jogos do Dia'!$A$2:$A$5,MATCH($A6,'Jogos do Dia'!$B$2:$B$5,0))-B6)<=180,15%,0%)))))) -> #N/A | AK6: =AG6*AH6*AI6 -> #N/A
W7: =IF(AND(F7>1,G7>1),"Sim","Não") -> Não | X7: =F7-G7 -> 0 | Y7: =IF(F7>G7,"V",IF(F7=G7,"E","D")) -> E | AG7: =1-(ABS(AB7-INDEX('Jogos do Dia'!$G$2:$G$5,MATCH($A7,'Jogos do Dia'!$B$2:$B$5,0)))+ABS(AC7-INDEX('Jogos do Dia'!$H$2:$H$5,MATCH($A7,'Jogos do Dia'!$B$2:$B$5,0)))+ABS(AD7-INDEX('Jogos do Dia'!$I$2:$I$5,MATCH($A7,'Jogos do Dia'!$B$2:$B$5,0)))+ABS(AE7-INDEX('Jogos do Dia'!$J$2:$J$5,MATCH($A7,'Jogos do Dia'!$B$2:$B$5,0)))+ABS(AF7-INDEX('Jogos do Dia'!$K$2:$K$5,MATCH($A7,'Jogos do Dia'!$B$2:$B$5,0))))/20 -> #N/A | AH7: =1-ABS(Z7-INDEX('Jogos do Dia'!$F$2:$F$5,MATCH($A7,'Jogos do Dia'!$B$2:$B$5,0))) -> #N/A | AI7: =IF((INDEX('Jogos do Dia'!$A$2:$A$5,MATCH($A7,'Jogos do Dia'!$B$2:$B$5,0))-B7)<=10,100%,IF((INDEX('Jogos do Dia'!$A$2:$A$5,MATCH($A7,'Jogos do Dia'!$B$2:$B$5,0))-B7)<=20,85%,IF((INDEX('Jogos do Dia'!$A$2:$A$5,MATCH($A7,'Jogos do Dia'!$B$2:$B$5,0))-B7)<=30,70%,IF((INDEX('Jogos do Dia'!$A$2:$A$5,MATCH($A7,'Jogos do Dia'!$B$2:$B$5,0))-B7)<=45,50%,IF((INDEX('Jogos do Dia'!$A$2:$A$5,MATCH($A7,'Jogos do Dia'!$B$2:$B$5,0))-B7)<=90,30%,IF((INDEX('Jogos do Dia'!$A$2:$A$5,MATCH($A7,'Jogos do Dia'!$B$2:$B$5,0))-B7)<=180,15%,0%)))))) -> #N/A | AK7: =AG7*AH7*AI7 -> #N/A
W8: =IF(AND(F8>1,G8>1),"Sim","Não") -> Não | X8: =F8-G8 -> 0 | Y8: =IF(F8>G8,"V",IF(F8=G8,"E","D")) -> E | AG8: =1-(ABS(AB8-INDEX('Jogos do Dia'!$G$2:$G$5,MATCH($A8,'Jogos do Dia'!$B$2:$B$5,0)))+ABS(AC8-INDEX('Jogos do Dia'!$H$2:$H$5,MATCH($A8,'Jogos do Dia'!$B$2:$B$5,0)))+ABS(AD8-INDEX('Jogos do Dia'!$I$2:$I$5,MATCH($A8,'Jogos do Dia'!$B$2:$B$5,0)))+ABS(AE8-INDEX('Jogos do Dia'!$J$2:$J$5,MATCH($A8,'Jogos do Dia'!$B$2:$B$5,0)))+ABS(AF8-INDEX('Jogos do Dia'!$K$2:$K$5,MATCH($A8,'Jogos do Dia'!$B$2:$B$5,0))))/20 -> #N/A | AH8: =1-ABS(Z8-INDEX('Jogos do Dia'!$F$2:$F$5,MATCH($A8,'Jogos do Dia'!$B$2:$B$5,0))) -> #N/A | AI8: =IF((INDEX('Jogos do Dia'!$A$2:$A$5,MATCH($A8,'Jogos do Dia'!$B$2:$B$5,0))-B8)<=10,100%,IF((INDEX('Jogos do Dia'!$A$2:$A$5,MATCH($A8,'Jogos do Dia'!$B$2:$B$5,0))-B8)<=20,85%,IF((INDEX('Jogos do Dia'!$A$2:$A$5,MATCH($A8,'Jogos do Dia'!$B$2:$B$5,0))-B8)<=30,70%,IF((INDEX('Jogos do Dia'!$A$2:$A$5,MATCH($A8,'Jogos do Dia'!$B$2:$B$5,0))-B8)<=45,50%,IF((INDEX('Jogos do Dia'!$A$2:$A$5,MATCH($A8,'Jogos do Dia'!$B$2:$B$5,0))-B8)<=90,30%,IF((INDEX('Jogos do Dia'!$A$2:$A$5,MATCH($A8,'Jogos do Dia'!$B$2:$B$5,0))-B8)<=180,15%,0%)))))) -> #N/A | AK8: =AG8*AH8*AI8 -> #N/A
W9: =IF(AND(F9>1,G9>1),"Sim","Não") -> Não | X9: =F9-G9 -> 0 | Y9: =IF(F9>G9,"V",IF(F9=G9,"E","D")) -> E | AG9: =1-(ABS(AB9-INDEX('Jogos do Dia'!$G$2:$G$5,MATCH($A9,'Jogos do Dia'!$B$2:$B$5,0)))+ABS(AC9-INDEX('Jogos do Dia'!$H$2:$H$5,MATCH($A9,'Jogos do Dia'!$B$2:$B$5,0)))+ABS(AD9-INDEX('Jogos do Dia'!$I$2:$I$5,MATCH($A9,'Jogos do Dia'!$B$2:$B$5,0)))+ABS(AE9-INDEX('Jogos do Dia'!$J$2:$J$5,MATCH($A9,'Jogos do Dia'!$B$2:$B$5,0)))+ABS(AF9-INDEX('Jogos do Dia'!$K$2:$K$5,MATCH($A9,'Jogos do Dia'!$B$2:$B$5,0))))/20 -> #N/A | AH9: =1-ABS(Z9-INDEX('Jogos do Dia'!$F$2:$F$5,MATCH($A9,'Jogos do Dia'!$B$2:$B$5,0))) -> #N/A | AI9: =IF((INDEX('Jogos do Dia'!$A$2:$A$5,MATCH($A9,'Jogos do Dia'!$B$2:$B$5,0))-B9)<=10,100%,IF((INDEX('Jogos do Dia'!$A$2:$A$5,MATCH($A9,'Jogos do Dia'!$B$2:$B$5,0))-B9)<=20,85%,IF((INDEX('Jogos do Dia'!$A$2:$A$5,MATCH($A9,'Jogos do Dia'!$B$2:$B$5,0))-B9)<=30,70%,IF((INDEX('Jogos do Dia'!$A$2:$A$5,MATCH($A9,'Jogos do Dia'!$B$2:$B$5,0))-B9)<=45,50%,IF((INDEX('Jogos do Dia'!$A$2:$A$5,MATCH($A9,'Jogos do Dia'!$B$2:$B$5,0))-B9)<=90,30%,IF((INDEX('Jogos do Dia'!$A$2:$A$5,MATCH($A9,'Jogos do Dia'!$B$2:$B$5,0))-B9)<=180,15%,0%)))))) -> #N/A | AK9: =AG9*AH9*AI9 -> #N/A
W10: =IF(AND(F10>1,G10>1),"Sim","Não") -> Não | X10: =F10-G10 -> 0 | Y10: =IF(F10>G10,"V",IF(F10=G10,"E","D")) -> E | AG10: =1-(ABS(AB10-INDEX('Jogos do Dia'!$G$2:$G$5,MATCH($A10,'Jogos do Dia'!$B$2:$B$5,0)))+ABS(AC10-INDEX('Jogos do Dia'!$H$2:$H$5,MATCH($A10,'Jogos do Dia'!$B$2:$B$5,0)))+ABS(AD10-INDEX('Jogos do Dia'!$I$2:$I$5,MATCH($A10,'Jogos do Dia'!$B$2:$B$5,0)))+ABS(AE10-INDEX('Jogos do Dia'!$J$2:$J$5,MATCH($A10,'Jogos do Dia'!$B$2:$B$5,0)))+ABS(AF10-INDEX('Jogos do Dia'!$K$2:$K$5,MATCH($A10,'Jogos do Dia'!$B$2:$B$5,0))))/20 -> #N/A | AH10: =1-ABS(Z10-INDEX('Jogos do Dia'!$F$2:$F$5,MATCH($A10,'Jogos do Dia'!$B$2:$B$5,0))) -> #N/A | AI10: =IF((INDEX('Jogos do Dia'!$A$2:$A$5,MATCH($A10,'Jogos do Dia'!$B$2:$B$5,0))-B10)<=10,100%,IF((INDEX('Jogos do Dia'!$A$2:$A$5,MATCH($A10,'Jogos do Dia'!$B$2:$B$5,0))-B10)<=20,85%,IF((INDEX('Jogos do Dia'!$A$2:$A$5,MATCH($A10,'Jogos do Dia'!$B$2:$B$5,0))-B10)<=30,70%,IF((INDEX('Jogos do Dia'!$A$2:$A$5,MATCH($A10,'Jogos do Dia'!$B$2:$B$5,0))-B10)<=45,50%,IF((INDEX('Jogos do Dia'!$A$2:$A$5,MATCH($A10,'Jogos do Dia'!$B$2:$B$5,0))-B10)<=90,30%,IF((INDEX('Jogos do Dia'!$A$2:$A$5,MATCH($A10,'Jogos do Dia'!$B$2:$B$5,0))-B10)<=180,15%,0%)))))) -> #N/A | AK10: =AG10*AH10*AI10 -> #N/A
W11: =IF(AND(F11>1,G11>1),"Sim","Não") -> Não | X11: =F11-G11 -> 0 | Y11: =IF(F11>G11,"V",IF(F11=G11,"E","D")) -> E | AG11: =1-(ABS(AB11-INDEX('Jogos do Dia'!$G$2:$G$5,MATCH($A11,'Jogos do Dia'!$B$2:$B$5,0)))+ABS(AC11-INDEX('Jogos do Dia'!$H$2:$H$5,MATCH($A11,'Jogos do Dia'!$B$2:$B$5,0)))+ABS(AD11-INDEX('Jogos do Dia'!$I$2:$I$5,MATCH($A11,'Jogos do Dia'!$B$2:$B$5,0)))+ABS(AE11-INDEX('Jogos do Dia'!$J$2:$J$5,MATCH($A11,'Jogos do Dia'!$B$2:$B$5,0)))+ABS(AF11-INDEX('Jogos do Dia'!$K$2:$K$5,MATCH($A11,'Jogos do Dia'!$B$2:$B$5,0))))/20 -> #N/A | AH11: =1-ABS(Z11-INDEX('Jogos do Dia'!$F$2:$F$5,MATCH($A11,'Jogos do Dia'!$B$2:$B$5,0))) -> #N/A | AI11: =IF((INDEX('Jogos do Dia'!$A$2:$A$5,MATCH($A11,'Jogos do Dia'!$B$2:$B$5,0))-B11)<=10,100%,IF((INDEX('Jogos do Dia'!$A$2:$A$5,MATCH($A11,'Jogos do Dia'!$B$2:$B$5,0))-B11)<=20,85%,IF((INDEX('Jogos do Dia'!$A$2:$A$5,MATCH($A11,'Jogos do Dia'!$B$2:$B$5,0))-B11)<=30,70%,IF((INDEX('Jogos do Dia'!$A$2:$A$5,MATCH($A11,'Jogos do Dia'!$B$2:$B$5,0))-B11)<=45,50%,IF((INDEX('Jogos do Dia'!$A$2:$A$5,MATCH($A11,'Jogos do Dia'!$B$2:$B$5,0))-B11)<=90,30%,IF((INDEX('Jogos do Dia'!$A$2:$A$5,MATCH($A11,'Jogos do Dia'!$B$2:$B$5,0))-B11)<=180,15%,0%)))))) -> #N/A | AK11: =AG11*AH11*AI11 -> #N/A
W12: =IF(AND(F12>1,G12>1),"Sim","Não") -> Não | X12: =F12-G12 -> 0 | Y12: =IF(F12>G12,"V",IF(F12=G12,"E","D")) -> E | AG12: =1-(ABS(AB12-INDEX('Jogos do Dia'!$G$2:$G$5,MATCH($A12,'Jogos do Dia'!$B$2:$B$5,0)))+ABS(AC12-INDEX('Jogos do Dia'!$H$2:$H$5,MATCH($A12,'Jogos do Dia'!$B$2:$B$5,0)))+ABS(AD12-INDEX('Jogos do Dia'!$I$2:$I$5,MATCH($A12,'Jogos do Dia'!$B$2:$B$5,0)))+ABS(AE12-INDEX('Jogos do Dia'!$J$2:$J$5,MATCH($A12,'Jogos do Dia'!$B$2:$B$5,0)))+ABS(AF12-INDEX('Jogos do Dia'!$K$2:$K$5,MATCH($A12,'Jogos do Dia'!$B$2:$B$5,0))))/20 -> #N/A | AH12: =1-ABS(Z12-INDEX('Jogos do Dia'!$F$2:$F$5,MATCH($A12,'Jogos do Dia'!$B$2:$B$5,0))) -> #N/A | AI12: =IF((INDEX('Jogos do Dia'!$A$2:$A$5,MATCH($A12,'Jogos do Dia'!$B$2:$B$5,0))-B12)<=10,100%,IF((INDEX('Jogos do Dia'!$A$2:$A$5,MATCH($A12,'Jogos do Dia'!$B$2:$B$5,0))-B12)<=20,85%,IF((INDEX('Jogos do Dia'!$A$2:$A$5,MATCH($A12,'Jogos do Dia'!$B$2:$B$5,0))-B12)<=30,70%,IF((INDEX('Jogos do Dia'!$A$2:$A$5,MATCH($A12,'Jogos do Dia'!$B$2:$B$5,0))-B12)<=45,50%,IF((INDEX('Jogos do Dia'!$A$2:$A$5,MATCH($A12,'Jogos do Dia'!$B$2:$B$5,0))-B12)<=90,30%,IF((INDEX('Jogos do Dia'!$A$2:$A$5,MATCH($A12,'Jogos do Dia'!$B$2:$B$5,0))-B12)<=180,15%,0%)))))) -> #N/A | AK12: =AG12*AH12*AI12 -> #N/A
W13: =IF(AND(F13>1,G13>1),"Sim","Não") -> Não | X13: =F13-G13 -> 0 | Y13: =IF(F13>G13,"V",IF(F13=G13,"E","D")) -> E | AG13: =1-(ABS(AB13-INDEX('Jogos do Dia'!$G$2:$G$5,MATCH($A13,'Jogos do Dia'!$B$2:$B$5,0)))+ABS(AC13-INDEX('Jogos do Dia'!$H$2:$H$5,MATCH($A13,'Jogos do Dia'!$B$2:$B$5,0)))+ABS(AD13-INDEX('Jogos do Dia'!$I$2:$I$5,MATCH($A13,'Jogos do Dia'!$B$2:$B$5,0)))+ABS(AE13-INDEX('Jogos do Dia'!$J$2:$J$5,MATCH($A13,'Jogos do Dia'!$B$2:$B$5,0)))+ABS(AF13-INDEX('Jogos do Dia'!$K$2:$K$5,MATCH($A13,'Jogos do Dia'!$B$2:$B$5,0))))/20 -> #N/A | AH13: =1-ABS(Z13-INDEX('Jogos do Dia'!$F$2:$F$5,MATCH($A13,'Jogos do Dia'!$B$2:$B$5,0))) -> #N/A | AI13: =IF((INDEX('Jogos do Dia'!$A$2:$A$5,MATCH($A13,'Jogos do Dia'!$B$2:$B$5,0))-B13)<=10,100%,IF((INDEX('Jogos do Dia'!$A$2:$A$5,MATCH($A13,'Jogos do Dia'!$B$2:$B$5,0))-B13)<=20,85%,IF((INDEX('Jogos do Dia'!$A$2:$A$5,MATCH($A13,'Jogos do Dia'!$B$2:$B$5,0))-B13)<=30,70%,IF((INDEX('Jogos do Dia'!$A$2:$A$5,MATCH($A13,'Jogos do Dia'!$B$2:$B$5,0))-B13)<=45,50%,IF((INDEX('Jogos do Dia'!$A$2:$A$5,MATCH($A13,'Jogos do Dia'!$B$2:$B$5,0))-B13)<=90,30%,IF((INDEX('Jogos do Dia'!$A$2:$A$5,MATCH($A13,'Jogos do Dia'!$B$2:$B$5,0))-B13)<=180,15%,0%)))))) -> #N/A | AK13: =AG13*AH13*AI13 -> #N/A
... W61: =IF(AND(F61>1,G61>1),"Sim","Não") -> Não | X61: =F61-G61 -> 0 | Y61: =IF(F61>G61,"V",IF(F61=G61,"E","D")) -> E | AG61: =1-(ABS(AB61-INDEX('Jogos do Dia'!$G$2:$G$5,MATCH($A61,'Jogos do Dia'!$B$2:$B$5,0)))+ABS(AC61-INDEX('Jogos do Dia'!$H$2:$H$5,MATCH($A61,'Jogos do Dia'!$B$2:$B$5,0)))+ABS(AD61-INDEX('Jogos do Dia'!$I$2:$I$5,MATCH($A61,'Jogos do Dia'!$B$2:$B$5,0)))+ABS(AE61-INDEX('Jogos do Dia'!$J$2:$J$5,MATCH($A61,'Jogos do Dia'!$B$2:$B$5,0)))+ABS(AF61-INDEX('Jogos do Dia'!$K$2:$K$5,MATCH($A61,'Jogos do Dia'!$B$2:$B$5,0))))/20 -> #N/A | AH61: =1-ABS(Z61-INDEX('Jogos do Dia'!$F$2:$F$5,MATCH($A61,'Jogos do Dia'!$B$2:$B$5,0))) -> #N/A | AI61: =IF((INDEX('Jogos do Dia'!$A$2:$A$5,MATCH($A61,'Jogos do Dia'!$B$2:$B$5,0))-B61)<=10,100%,IF((INDEX('Jogos do Dia'!$A$2:$A$5,MATCH($A61,'Jogos do Dia'!$B$2:$B$5,0))-B61)<=20,85%,IF((INDEX('Jogos do Dia'!$A$2:$A$5,MATCH($A61,'Jogos do Dia'!$B$2:$B$5,0))-B61)<=30,70%,IF((INDEX('Jogos do Dia'!$A$2:$A$5,MATCH($A61,'Jogos do Dia'!$B$2:$B$5,0))-B61)<=45,50%,IF((INDEX('Jogos do Dia'!$A$2:$A$5,MATCH($A61,'Jogos do Dia'!$B$2:$B$5,0))-B61)<=90,30%,IF((INDEX('Jogos do Dia'!$A$2:$A$5,MATCH($A61,'Jogos do Dia'!$B$2:$B$5,0))-B61)<=180,15%,0%)))))) -> #N/A | AK61: =AG61*AH61*AI61 -> #N/A

Sheet Jogos do Dia
A1: Data | B1: Time | C1: Adversário | D1: Estilo Time | E1: Estilo Adversário | F1: Favoristismo | G1: Bloco Baixo (1-5) | H1: Pressão Alta (1-5) | I1: Transição (1-5) | J1: Posse (1-5) | K1: Bola Parada (1-5) | L1: Ataca Fundo? (S/N) | M1: Contexto/Classificação | N1: Observações | O1: Gols Pró | P1: Gols Contra | Q1: Gols Total | R1: Cartões Pró | S1: Cartões Contra | T1: Cartões Total | U1: Escanteios Pró | V1: Escanteios Contra | W1: Escanteios Total | X1: Chutes Pró | Y1: Chutes Contra | Z1: Chutes Total | AA1: Chutes Gol Pró | AB1: Chutes Gol Contra | AC1: Chutes a gol Total | AD1: Gols 1T Pró | AE1: Gols 1T Contra | AF1: Gols 1T Total | AG1: BTTS | AH1: Confiab Filtro | AJ1: Chave
A2: 06/07/2026 | B2: Portugal | C2: Spain | D2: Posse, talento, Ronaldo | E2: Posse dominante, Yamal | F2: 0.233 | G2: 1 | H2: 5 | I2: 4 | J2: 5 | K2: 3 | L2: N | M2: Mata-mata equilibrado. Ambos posse (não bloco baixo), nenhum ataca a linha de fundo → jogo comprimido, poucos cantos, Under com leve suporte. | O2: {=IFERROR(SUMPRODUCT((Times!$A$2:$A$61=$B2)*(Times!$AG$2:$AG$61>=65%)*(Times!$AH$2:$AH$61>=65%)*Times!$F$2:$F$61*Times!$AK$2:$AK$61)/SUMPRODUCT((Times!$A$2:$A$61=$B2)*(Times!$AG$2:$AG$61>=65%)*(Times!$AH$2:$AH$61>=65%)*Times!$AK$2:$AK$61),0)} -> 0 | P2: {=IFERROR(SUMPRODUCT((Times!$A$2:$A$61=$B2)*(Times!$AG$2:$AG$61>=65%)*(Times!$AH$2:$AH$61>=65%)*Times!$G$2:$G$61*Times!$AK$2:$AK$61)/SUMPRODUCT((Times!$A$2:$A$61=$B2)*(Times!$AG$2:$AG$61>=65%)*(Times!$AH$2:$AH$61>=65%)*Times!$AK$2:$AK$61),0)} -> 0 | Q2: =Tabela26[[#This Row],[Gols Pró]]+Tabela26[[#This Row],[Gols Contra]] -> 0 | R2: {=IFERROR(_xlfn.LET(_xlpm.tm,$B2,_xlpm.vals,_xlfn._xlws.FILTER(Times!$L$2:$L$61,Times!$A$2:$A$61=_xlpm.tm),_xlpm.ag,_xlfn._xlws.FILTER(Times!$AG$2:$AG$61,Times!$A$2:$A$61=_xlpm.tm),_xlpm.ah,_xlfn._xlws.FILTER(Times!$AH$2:$AH$61,Times!$A$2:$A$61=_xlpm.tm),_xlpm.ai,_xlfn._xlws.FILTER(Times!$AI$2:$AI$61,Times!$A$2:$A$61=_xlpm.tm),_xlpm.wt,_xlpm.ag*50%+_xlpm.ah*30%+_xlpm.ai*20%,_xlpm.n,ROWS(_xlpm.vals),_xlpm.avg,AVERAGE(_xlpm.vals),_xlpm.sd,IF(_xlpm.n>1,_xlfn.STDEV.S(_xlpm.vals),0),_xlpm.mask,IF(_xlpm.n<3,_xlfn.SEQUENCE(_xlpm.n,1,1,0)=1,ABS(_xlpm.vals-_xlpm.avg)<=_xlpm.sd)*(_xlpm.ag>=65%)*(_xlpm.ah>=65%),AVERAGE(_xlfn._xlws.FILTER(_xlpm.vals*_xlpm.wt,_xlpm.mask))),0)} -> 0 | S2: {=IFERROR(_xlfn.LET(_xlpm.tm,$B2,_xlpm.vals,_xlfn._xlws.FILTER(Times!$M$2:$M$61,Times!$A$2:$A$61=_xlpm.tm),_xlpm.ag,_xlfn._xlws.FILTER(Times!$AG$2:$AG$61,Times!$A$2:$A$61=_xlpm.tm),_xlpm.ah,_xlfn._xlws.FILTER(Times!$AH$2:$AH$61,Times!$A$2:$A$61=_xlpm.tm),_xlpm.ai,_xlfn._xlws.FILTER(Times!$AI$2:$AI$61,Times!$A$2:$A$61=_xlpm.tm),_xlpm.wt,_xlpm.ag*50%+_xlpm.ah*30%+_xlpm.ai*20%,_xlpm.n,ROWS(_xlpm.vals),_xlpm.avg,AVERAGE(_xlpm.vals),_xlpm.sd,IF(_xlpm.n>1,_xlfn.STDEV.S(_xlpm.vals),0),_xlpm.mask,IF(_xlpm.n<3,_xlfn.SEQUENCE(_xlpm.n,1,1,0)=1,ABS(_xlpm.vals-_xlpm.avg)<=_xlpm.sd)*(_xlpm.ag>=65%)*(_xlpm.ah>=65%),AVERAGE(_xlfn._xlws.FILTER(_xlpm.vals*_xlpm.wt,_xlpm.mask))),0)} -> 0 | T2: =Tabela26[[#This Row],[Cartões Pró]]+Tabela26[[#This Row],[Cartões Contra]] -> 0 | U2: {=IFERROR(_xlfn.LET(_xlpm.tm,$B2,_xlpm.vals,_xlfn._xlws.FILTER(Times!$J$2:$J$61,Times!$A$2:$A$61=_xlpm.tm),_xlpm.ag,_xlfn._xlws.FILTER(Times!$AG$2:$AG$61,Times!$A$2:$A$61=_xlpm.tm),_xlpm.ah,_xlfn._xlws.FILTER(Times!$AH$2:$AH$61,Times!$A$2:$A$61=_xlpm.tm),_xlpm.ai,_xlfn._xlws.FILTER(Times!$AI$2:$AI$61,Times!$A$2:$A$61=_xlpm.tm),_xlpm.wt,_xlpm.ag*50%+_xlpm.ah*30%+_xlpm.ai*20%,_xlpm.n,ROWS(_xlpm.vals),_xlpm.avg,AVERAGE(_xlpm.vals),_xlpm.sd,IF(_xlpm.n>1,_xlfn.STDEV.S(_xlpm.vals),0),_xlpm.mask,IF(_xlpm.n<3,_xlfn.SEQUENCE(_xlpm.n,1,1,0)=1,ABS(_xlpm.vals-_xlpm.avg)<=_xlpm.sd)*(_xlpm.ag>=65%)*(_xlpm.ah>=65%),AVERAGE(_xlfn._xlws.FILTER(_xlpm.vals*_xlpm.wt,_xlpm.mask))),0)} -> 0 | V2: {=IFERROR(_xlfn.LET(_xlpm.tm,$B2,_xlpm.vals,_xlfn._xlws.FILTER(Times!$K$2:$K$61,Times!$A$2:$A$61=_xlpm.tm),_xlpm.ag,_xlfn._xlws.FILTER(Times!$AG$2:$AG$61,Times!$A$2:$A$61=_xlpm.tm),_xlpm.ah,_xlfn._xlws.FILTER(Times!$AH$2:$AH$61,Times!$A$2:$A$61=_xlpm.tm),_xlpm.ai,_xlfn._xlws.FILTER(Times!$AI$2:$AI$61,Times!$A$2:$A$61=_xlpm.tm),_xlpm.wt,_xlpm.ag*50%+_xlpm.ah*30%+_xlpm.ai*20%,_xlpm.n,ROWS(_xlpm.vals),_xlpm.avg,AVERAGE(_xlpm.vals),_xlpm.sd,IF(_xlpm.n>1,_xlfn.STDEV.S(_xlpm.vals),0),_xlpm.mask,IF(_xlpm.n<3,_xlfn.SEQUENCE(_xlpm.n,1,1,0)=1,ABS(_xlpm.vals-_xlpm.avg)<=_xlpm.sd)*(_xlpm.ag>=65%)*(_xlpm.ah>=65%),AVERAGE(_xlfn._xlws.FILTER(_xlpm.vals*_xlpm.wt,_xlpm.mask))),0)} -> 0 | W2: =Tabela26[[#This Row],[Escanteios Pró]]+Tabela26[[#This Row],[Escanteios Contra]] -> 0 | X2: {=IFERROR(_xlfn.LET(_xlpm.tm,$B2,_xlpm.vals,_xlfn._xlws.FILTER(Times!$N$2:$N$61,Times!$A$2:$A$61=_xlpm.tm),_xlpm.ag,_xlfn._xlws.FILTER(Times!$AG$2:$AG$61,Times!$A$2:$A$61=_xlpm.tm),_xlpm.ah,_xlfn._xlws.FILTER(Times!$AH$2:$AH$61,Times!$A$2:$A$61=_xlpm.tm),_xlpm.ai,_xlfn._xlws.FILTER(Times!$AI$2:$AI$61,Times!$A$2:$A$61=_xlpm.tm),_xlpm.wt,_xlpm.ag*50%+_xlpm.ah*30%+_xlpm.ai*20%,_xlpm.n,ROWS(_xlpm.vals),_xlpm.avg,AVERAGE(_xlpm.vals),_xlpm.sd,IF(_xlpm.n>1,_xlfn.STDEV.S(_xlpm.vals),0),_xlpm.mask,IF(_xlpm.n<3,_xlfn.SEQUENCE(_xlpm.n,1,1,0)=1,ABS(_xlpm.vals-_xlpm.avg)<=_xlpm.sd)*(_xlpm.ag>=65%)*(_xlpm.ah>=65%),AVERAGE(_xlfn._xlws.FILTER(_xlpm.vals*_xlpm.wt,_xlpm.mask))),0)} -> 0 | Y2: {=IFERROR(_xlfn.LET(_xlpm.tm,$B2,_xlpm.vals,_xlfn._xlws.FILTER(Times!$O$2:$O$61,Times!$A$2:$A$61=_xlpm.tm),_xlpm.ag,_xlfn._xlws.FILTER(Times!$AG$2:$AG$61,Times!$A$2:$A$61=_xlpm.tm),_xlpm.ah,_xlfn._xlws.FILTER(Times!$AH$2:$AH$61,Times!$A$2:$A$61=_xlpm.tm),_xlpm.ai,_xlfn._xlws.FILTER(Times!$AI$2:$AI$61,Times!$A$2:$A$61=_xlpm.tm),_xlpm.wt,_xlpm.ag*50%+_xlpm.ah*30%+_xlpm.ai*20%,_xlpm.n,ROWS(_xlpm.vals),_xlpm.avg,AVERAGE(_xlpm.vals),_xlpm.sd,IF(_xlpm.n>1,_xlfn.STDEV.S(_xlpm.vals),0),_xlpm.mask,IF(_xlpm.n<3,_xlfn.SEQUENCE(_xlpm.n,1,1,0)=1,ABS(_xlpm.vals-_xlpm.avg)<=_xlpm.sd)*(_xlpm.ag>=65%)*(_xlpm.ah>=65%),AVERAGE(_xlfn._xlws.FILTER(_xlpm.vals*_xlpm.wt,_xlpm.mask))),0)} -> 0 | Z2: =Tabela26[[#This Row],[Chutes Pró]]+Tabela26[[#This Row],[Chutes Contra]] -> 0 | AA2: {=IFERROR(_xlfn.LET(_xlpm.tm,$B2,_xlpm.vals,_xlfn._xlws.FILTER(Times!$P$2:$P$61,Times!$A$2:$A$61=_xlpm.tm),_xlpm.ag,_xlfn._xlws.FILTER(Times!$AG$2:$AG$61,Times!$A$2:$A$61=_xlpm.tm),_xlpm.ah,_xlfn._xlws.FILTER(Times!$AH$2:$AH$61,Times!$A$2:$A$61=_xlpm.tm),_xlpm.ai,_xlfn._xlws.FILTER(Times!$AI$2:$AI$61,Times!$A$2:$A$61=_xlpm.tm),_xlpm.wt,_xlpm.ag*50%+_xlpm.ah*30%+_xlpm.ai*20%,_xlpm.n,ROWS(_xlpm.vals),_xlpm.avg,AVERAGE(_xlpm.vals),_xlpm.sd,IF(_xlpm.n>1,_xlfn.STDEV.S(_xlpm.vals),0),_xlpm.mask,IF(_xlpm.n<3,_xlfn.SEQUENCE(_xlpm.n,1,1,0)=1,ABS(_xlpm.vals-_xlpm.avg)<=_xlpm.sd)*(_xlpm.ag>=65%)*(_xlpm.ah>=65%),AVERAGE(_xlfn._xlws.FILTER(_xlpm.vals*_xlpm.wt,_xlpm.mask))),0)} -> 0 | AB2: {=IFERROR(_xlfn.LET(_xlpm.tm,$B2,_xlpm.vals,_xlfn._xlws.FILTER(Times!$Q$2:$Q$61,Times!$A$2:$A$61=_xlpm.tm),_xlpm.ag,_xlfn._xlws.FILTER(Times!$AG$2:$AG$61,Times!$A$2:$A$61=_xlpm.tm),_xlpm.ah,_xlfn._xlws.FILTER(Times!$AH$2:$AH$61,Times!$A$2:$A$61=_xlpm.tm),_xlpm.ai,_xlfn._xlws.FILTER(Times!$AI$2:$AI$61,Times!$A$2:$A$61=_xlpm.tm),_xlpm.wt,_xlpm.ag*50%+_xlpm.ah*30%+_xlpm.ai*20%,_xlpm.n,ROWS(_xlpm.vals),_xlpm.avg,AVERAGE(_xlpm.vals),_xlpm.sd,IF(_xlpm.n>1,_xlfn.STDEV.S(_xlpm.vals),0),_xlpm.mask,IF(_xlpm.n<3,_xlfn.SEQUENCE(_xlpm.n,1,1,0)=1,ABS(_xlpm.vals-_xlpm.avg)<=_xlpm.sd)*(_xlpm.ag>=65%)*(_xlpm.ah>=65%),AVERAGE(_xlfn._xlws.FILTER(_xlpm.vals*_xlpm.wt,_xlpm.mask))),0)} -> 0 | AC2: =Tabela26[[#This Row],[Chutes Gol Pró]]+Tabela26[[#This Row],[Chutes Gol Contra]] -> 0 | AD2: {=IFERROR(_xlfn.LET(_xlpm.tm,$B2,_xlpm.vals,_xlfn._xlws.FILTER(Times!$U$2:$U$61,Times!$A$2:$A$61=_xlpm.tm),_xlpm.ag,_xlfn._xlws.FILTER(Times!$AG$2:$AG$61,Times!$A$2:$A$61=_xlpm.tm),_xlpm.ah,_xlfn._xlws.FILTER(Times!$AH$2:$AH$61,Times!$A$2:$A$61=_xlpm.tm),_xlpm.ai,_xlfn._xlws.FILTER(Times!$AI$2:$AI$61,Times!$A$2:$A$61=_xlpm.tm),_xlpm.wt,_xlpm.ag*50%+_xlpm.ah*30%+_xlpm.ai*20%,_xlpm.n,ROWS(_xlpm.vals),_xlpm.avg,AVERAGE(_xlpm.vals),_xlpm.sd,IF(_xlpm.n>1,_xlfn.STDEV.S(_xlpm.vals),0),_xlpm.mask,IF(_xlpm.n<3,_xlfn.SEQUENCE(_xlpm.n,1,1,0)=1,ABS(_xlpm.vals-_xlpm.avg)<=_xlpm.sd)*(_xlpm.ag>=65%)*(_xlpm.ah>=65%),AVERAGE(_xlfn._xlws.FILTER(_xlpm.vals*_xlpm.wt,_xlpm.mask))),0)} -> 0 | AE2: {=IFERROR(_xlfn.LET(_xlpm.tm,$B2,_xlpm.vals,_xlfn._xlws.FILTER(Times!$V$2:$V$61,Times!$A$2:$A$61=_xlpm.tm),_xlpm.ag,_xlfn._xlws.FILTER(Times!$AG$2:$AG$61,Times!$A$2:$A$61=_xlpm.tm),_xlpm.ah,_xlfn._xlws.FILTER(Times!$AH$2:$AH$61,Times!$A$2:$A$61=_xlpm.tm),_xlpm.ai,_xlfn._xlws.FILTER(Times!$AI$2:$AI$61,Times!$A$2:$A$61=_xlpm.tm),_xlpm.wt,_xlpm.ag*50%+_xlpm.ah*30%+_xlpm.ai*20%,_xlpm.n,ROWS(_xlpm.vals),_xlpm.avg,AVERAGE(_xlpm.vals),_xlpm.sd,IF(_xlpm.n>1,_xlfn.STDEV.S(_xlpm.vals),0),_xlpm.mask,IF(_xlpm.n<3,_xlfn.SEQUENCE(_xlpm.n,1,1,0)=1,ABS(_xlpm.vals-_xlpm.avg)<=_xlpm.sd)*(_xlpm.ag>=65%)*(_xlpm.ah>=65%),AVERAGE(_xlfn._xlws.FILTER(_xlpm.vals*_xlpm.wt,_xlpm.mask))),0)} -> 0 | AF2: =Tabela26[[#This Row],[Gols 1T Pró]]+Tabela26[[#This Row],[Gols 1T Contra]] -> 0 | AG2: =IF(AND(Tabela26[[#This Row],[Gols Pró]]>0.5,Tabela26[[#This Row],[Gols Contra]]>0.5),"Sim","Não") -> Não | AH2: =COUNTIFS(Tabela15[Time],Tabela26[[#This Row],[Time]],Tabela15[Aderência ao alvo (%)],">="&0.65,Tabela15[Favoritismo (preencher depois)],">="&Tabela26[[#This Row],[Favoristismo]]-0.2,Tabela15[Favoritismo (preencher depois)],"<="&Tabela26[[#This Row],[Favoristismo]]+0.2) -> 0 | AJ2: =B2&"|"&C2 -> Portugal|Spain
O3: {=IFERROR(SUMPRODUCT((Times!$A$2:$A$61=$B3)*(Times!$AG$2:$AG$61>=65%)*(Times!$AH$2:$AH$61>=65%)*Times!$F$2:$F$61*Times!$AK$2:$AK$61)/SUMPRODUCT((Times!$A$2:$A$61=$B3)*(Times!$AG$2:$AG$61>=65%)*(Times!$AH$2:$AH$61>=65%)*Times!$AK$2:$AK$61),0)} -> 0 | P3: {=IFERROR(SUMPRODUCT((Times!$A$2:$A$61=$B3)*(Times!$AG$2:$AG$61>=65%)*(Times!$AH$2:$AH$61>=65%)*Times!$G$2:$G$61*Times!$AK$2:$AK$61)/SUMPRODUCT((Times!$A$2:$A$61=$B3)*(Times!$AG$2:$AG$61>=65%)*(Times!$AH$2:$AH$61>=65%)*Times!$AK$2:$AK$61),0)} -> 0 | Q3: =Tabela26[[#This Row],[Gols Pró]]+Tabela26[[#This Row],[Gols Contra]] -> 0 | R3: {=IFERROR(_xlfn.LET(_xlpm.tm,$B3,_xlpm.vals,_xlfn._xlws.FILTER(Times!$L$2:$L$61,Times!$A$2:$A$61=_xlpm.tm),_xlpm.ag,_xlfn._xlws.FILTER(Times!$AG$2:$AG$61,Times!$A$2:$A$61=_xlpm.tm),_xlpm.ah,_xlfn._xlws.FILTER(Times!$AH$2:$AH$61,Times!$A$2:$A$61=_xlpm.tm),_xlpm.ai,_xlfn._xlws.FILTER(Times!$AI$2:$AI$61,Times!$A$2:$A$61=_xlpm.tm),_xlpm.wt,_xlpm.ag*50%+_xlpm.ah*30%+_xlpm.ai*20%,_xlpm.n,ROWS(_xlpm.vals),_xlpm.avg,AVERAGE(_xlpm.vals),_xlpm.sd,IF(_xlpm.n>1,_xlfn.STDEV.S(_xlpm.vals),0),_xlpm.mask,IF(_xlpm.n<3,_xlfn.SEQUENCE(_xlpm.n,1,1,0)=1,ABS(_xlpm.vals-_xlpm.avg)<=_xlpm.sd)*(_xlpm.ag>=65%)*(_xlpm.ah>=65%),AVERAGE(_xlfn._xlws.FILTER(_xlpm.vals*_xlpm.wt,_xlpm.mask))),0)} -> 0 | S3: {=IFERROR(_xlfn.LET(_xlpm.tm,$B3,_xlpm.vals,_xlfn._xlws.FILTER(Times!$M$2:$M$61,Times!$A$2:$A$61=_xlpm.tm),_xlpm.ag,_xlfn._xlws.FILTER(Times!$AG$2:$AG$61,Times!$A$2:$A$61=_xlpm.tm),_xlpm.ah,_xlfn._xlws.FILTER(Times!$AH$2:$AH$61,Times!$A$2:$A$61=_xlpm.tm),_xlpm.ai,_xlfn._xlws.FILTER(Times!$AI$2:$AI$61,Times!$A$2:$A$61=_xlpm.tm),_xlpm.wt,_xlpm.ag*50%+_xlpm.ah*30%+_xlpm.ai*20%,_xlpm.n,ROWS(_xlpm.vals),_xlpm.avg,AVERAGE(_xlpm.vals),_xlpm.sd,IF(_xlpm.n>1,_xlfn.STDEV.S(_xlpm.vals),0),_xlpm.mask,IF(_xlpm.n<3,_xlfn.SEQUENCE(_xlpm.n,1,1,0)=1,ABS(_xlpm.vals-_xlpm.avg)<=_xlpm.sd)*(_xlpm.ag>=65%)*(_xlpm.ah>=65%),AVERAGE(_xlfn._xlws.FILTER(_xlpm.vals*_xlpm.wt,_xlpm.mask))),0)} -> 0 | T3: =Tabela26[[#This Row],[Cartões Pró]]+Tabela26[[#This Row],[Cartões Contra]] -> 0 | U3: {=IFERROR(_xlfn.LET(_xlpm.tm,$B3,_xlpm.vals,_xlfn._xlws.FILTER(Times!$J$2:$J$61,Times!$A$2:$A$61=_xlpm.tm),_xlpm.ag,_xlfn._xlws.FILTER(Times!$AG$2:$AG$61,Times!$A$2:$A$61=_xlpm.tm),_xlpm.ah,_xlfn._xlws.FILTER(Times!$AH$2:$AH$61,Times!$A$2:$A$61=_xlpm.tm),_xlpm.ai,_xlfn._xlws.FILTER(Times!$AI$2:$AI$61,Times!$A$2:$A$61=_xlpm.tm),_xlpm.wt,_xlpm.ag*50%+_xlpm.ah*30%+_xlpm.ai*20%,_xlpm.n,ROWS(_xlpm.vals),_xlpm.avg,AVERAGE(_xlpm.vals),_xlpm.sd,IF(_xlpm.n>1,_xlfn.STDEV.S(_xlpm.vals),0),_xlpm.mask,IF(_xlpm.n<3,_xlfn.SEQUENCE(_xlpm.n,1,1,0)=1,ABS(_xlpm.vals-_xlpm.avg)<=_xlpm.sd)*(_xlpm.ag>=65%)*(_xlpm.ah>=65%),AVERAGE(_xlfn._xlws.FILTER(_xlpm.vals*_xlpm.wt,_xlpm.mask))),0)} -> 0 | V3: {=IFERROR(_xlfn.LET(_xlpm.tm,$B3,_xlpm.vals,_xlfn._xlws.FILTER(Times!$K$2:$K$61,Times!$A$2:$A$61=_xlpm.tm),_xlpm.ag,_xlfn._xlws.FILTER(Times!$AG$2:$AG$61,Times!$A$2:$A$61=_xlpm.tm),_xlpm.ah,_xlfn._xlws.FILTER(Times!$AH$2:$AH$61,Times!$A$2:$A$61=_xlpm.tm),_xlpm.ai,_xlfn._xlws.FILTER(Times!$AI$2:$AI$61,Times!$A$2:$A$61=_xlpm.tm),_xlpm.wt,_xlpm.ag*50%+_xlpm.ah*30%+_xlpm.ai*20%,_xlpm.n,ROWS(_xlpm.vals),_xlpm.avg,AVERAGE(_xlpm.vals),_xlpm.sd,IF(_xlpm.n>1,_xlfn.STDEV.S(_xlpm.vals),0),_xlpm.mask,IF(_xlpm.n<3,_xlfn.SEQUENCE(_xlpm.n,1,1,0)=1,ABS(_xlpm.vals-_xlpm.avg)<=_xlpm.sd)*(_xlpm.ag>=65%)*(_xlpm.ah>=65%),AVERAGE(_xlfn._xlws.FILTER(_xlpm.vals*_xlpm.wt,_xlpm.mask))),0)} -> 0 | W3: =Tabela26[[#This Row],[Escanteios Pró]]+Tabela26[[#This Row],[Escanteios Contra]] -> 0 | X3: {=IFERROR(_xlfn.LET(_xlpm.tm,$B3,_xlpm.vals,_xlfn._xlws.FILTER(Times!$N$2:$N$61,Times!$A$2:$A$61=_xlpm.tm),_xlpm.ag,_xlfn._xlws.FILTER(Times!$AG$2:$AG$61,Times!$A$2:$A$61=_xlpm.tm),_xlpm.ah,_xlfn._xlws.FILTER(Times!$AH$2:$AH$61,Times!$A$2:$A$61=_xlpm.tm),_xlpm.ai,_xlfn._xlws.FILTER(Times!$AI$2:$AI$61,Times!$A$2:$A$61=_xlpm.tm),_xlpm.wt,_xlpm.ag*50%+_xlpm.ah*30%+_xlpm.ai*20%,_xlpm.n,ROWS(_xlpm.vals),_xlpm.avg,AVERAGE(_xlpm.vals),_xlpm.sd,IF(_xlpm.n>1,_xlfn.STDEV.S(_xlpm.vals),0),_xlpm.mask,IF(_xlpm.n<3,_xlfn.SEQUENCE(_xlpm.n,1,1,0)=1,ABS(_xlpm.vals-_xlpm.avg)<=_xlpm.sd)*(_xlpm.ag>=65%)*(_xlpm.ah>=65%),AVERAGE(_xlfn._xlws.FILTER(_xlpm.vals*_xlpm.wt,_xlpm.mask))),0)} -> 0 | Y3: {=IFERROR(_xlfn.LET(_xlpm.tm,$B3,_xlpm.vals,_xlfn._xlws.FILTER(Times!$O$2:$O$61,Times!$A$2:$A$61=_xlpm.tm),_xlpm.ag,_xlfn._xlws.FILTER(Times!$AG$2:$AG$61,Times!$A$2:$A$61=_xlpm.tm),_xlpm.ah,_xlfn._xlws.FILTER(Times!$AH$2:$AH$61,Times!$A$2:$A$61=_xlpm.tm),_xlpm.ai,_xlfn._xlws.FILTER(Times!$AI$2:$AI$61,Times!$A$2:$A$61=_xlpm.tm),_xlpm.wt,_xlpm.ag*50%+_xlpm.ah*30%+_xlpm.ai*20%,_xlpm.n,ROWS(_xlpm.vals),_xlpm.avg,AVERAGE(_xlpm.vals),_xlpm.sd,IF(_xlpm.n>1,_xlfn.STDEV.S(_xlpm.vals),0),_xlpm.mask,IF(_xlpm.n<3,_xlfn.SEQUENCE(_xlpm.n,1,1,0)=1,ABS(_xlpm.vals-_xlpm.avg)<=_xlpm.sd)*(_xlpm.ag>=65%)*(_xlpm.ah>=65%),AVERAGE(_xlfn._xlws.FILTER(_xlpm.vals*_xlpm.wt,_xlpm.mask))),0)} -> 0 | Z3: =Tabela26[[#This Row],[Chutes Pró]]+Tabela26[[#This Row],[Chutes Contra]] -> 0 | AA3: {=IFERROR(_xlfn.LET(_xlpm.tm,$B3,_xlpm.vals,_xlfn._xlws.FILTER(Times!$P$2:$P$61,Times!$A$2:$A$61=_xlpm.tm),_xlpm.ag,_xlfn._xlws.FILTER(Times!$AG$2:$AG$61,Times!$A$2:$A$61=_xlpm.tm),_xlpm.ah,_xlfn._xlws.FILTER(Times!$AH$2:$AH$61,Times!$A$2:$A$61=_xlpm.tm),_xlpm.ai,_xlfn._xlws.FILTER(Times!$AI$2:$AI$61,Times!$A$2:$A$61=_xlpm.tm),_xlpm.wt,_xlpm.ag*50%+_xlpm.ah*30%+_xlpm.ai*20%,_xlpm.n,ROWS(_xlpm.vals),_xlpm.avg,AVERAGE(_xlpm.vals),_xlpm.sd,IF(_xlpm.n>1,_xlfn.STDEV.S(_xlpm.vals),0),_xlpm.mask,IF(_xlpm.n<3,_xlfn.SEQUENCE(_xlpm.n,1,1,0)=1,ABS(_xlpm.vals-_xlpm.avg)<=_xlpm.sd)*(_xlpm.ag>=65%)*(_xlpm.ah>=65%),AVERAGE(_xlfn._xlws.FILTER(_xlpm.vals*_xlpm.wt,_xlpm.mask))),0)} -> 0 | AB3: {=IFERROR(_xlfn.LET(_xlpm.tm,$B3,_xlpm.vals,_xlfn._xlws.FILTER(Times!$Q$2:$Q$61,Times!$A$2:$A$61=_xlpm.tm),_xlpm.ag,_xlfn._xlws.FILTER(Times!$AG$2:$AG$61,Times!$A$2:$A$61=_xlpm.tm),_xlpm.ah,_xlfn._xlws.FILTER(Times!$AH$2:$AH$61,Times!$A$2:$A$61=_xlpm.tm),_xlpm.ai,_xlfn._xlws.FILTER(Times!$AI$2:$AI$61,Times!$A$2:$A$61=_xlpm.tm),_xlpm.wt,_xlpm.ag*50%+_xlpm.ah*30%+_xlpm.ai*20%,_xlpm.n,ROWS(_xlpm.vals),_xlpm.avg,AVERAGE(_xlpm.vals),_xlpm.sd,IF(_xlpm.n>1,_xlfn.STDEV.S(_xlpm.vals),0),_xlpm.mask,IF(_xlpm.n<3,_xlfn.SEQUENCE(_xlpm.n,1,1,0)=1,ABS(_xlpm.vals-_xlpm.avg)<=_xlpm.sd)*(_xlpm.ag>=65%)*(_xlpm.ah>=65%),AVERAGE(_xlfn._xlws.FILTER(_xlpm.vals*_xlpm.wt,_xlpm.mask))),0)} -> 0 | AC3: =Tabela26[[#This Row],[Chutes Gol Pró]]+Tabela26[[#This Row],[Chutes Gol Contra]] -> 0 | AD3: {=IFERROR(_xlfn.LET(_xlpm.tm,$B3,_xlpm.vals,_xlfn._xlws.FILTER(Times!$U$2:$U$61,Times!$A$2:$A$61=_xlpm.tm),_xlpm.ag,_xlfn._xlws.FILTER(Times!$AG$2:$AG$61,Times!$A$2:$A$61=_xlpm.tm),_xlpm.ah,_xlfn._xlws.FILTER(Times!$AH$2:$AH$61,Times!$A$2:$A$61=_xlpm.tm),_xlpm.ai,_xlfn._xlws.FILTER(Times!$AI$2:$AI$61,Times!$A$2:$A$61=_xlpm.tm),_xlpm.wt,_xlpm.ag*50%+_xlpm.ah*30%+_xlpm.ai*20%,_xlpm.n,ROWS(_xlpm.vals),_xlpm.avg,AVERAGE(_xlpm.vals),_xlpm.sd,IF(_xlpm.n>1,_xlfn.STDEV.S(_xlpm.vals),0),_xlpm.mask,IF(_xlpm.n<3,_xlfn.SEQUENCE(_xlpm.n,1,1,0)=1,ABS(_xlpm.vals-_xlpm.avg)<=_xlpm.sd)*(_xlpm.ag>=65%)*(_xlpm.ah>=65%),AVERAGE(_xlfn._xlws.FILTER(_xlpm.vals*_xlpm.wt,_xlpm.mask))),0)} -> 0 | AE3: {=IFERROR(_xlfn.LET(_xlpm.tm,$B3,_xlpm.vals,_xlfn._xlws.FILTER(Times!$V$2:$V$61,Times!$A$2:$A$61=_xlpm.tm),_xlpm.ag,_xlfn._xlws.FILTER(Times!$AG$2:$AG$61,Times!$A$2:$A$61=_xlpm.tm),_xlpm.ah,_xlfn._xlws.FILTER(Times!$AH$2:$AH$61,Times!$A$2:$A$61=_xlpm.tm),_xlpm.ai,_xlfn._xlws.FILTER(Times!$AI$2:$AI$61,Times!$A$2:$A$61=_xlpm.tm),_xlpm.wt,_xlpm.ag*50%+_xlpm.ah*30%+_xlpm.ai*20%,_xlpm.n,ROWS(_xlpm.vals),_xlpm.avg,AVERAGE(_xlpm.vals),_xlpm.sd,IF(_xlpm.n>1,_xlfn.STDEV.S(_xlpm.vals),0),_xlpm.mask,IF(_xlpm.n<3,_xlfn.SEQUENCE(_xlpm.n,1,1,0)=1,ABS(_xlpm.vals-_xlpm.avg)<=_xlpm.sd)*(_xlpm.ag>=65%)*(_xlpm.ah>=65%),AVERAGE(_xlfn._xlws.FILTER(_xlpm.vals*_xlpm.wt,_xlpm.mask))),0)} -> 0 | AF3: =Tabela26[[#This Row],[Gols 1T Pró]]+Tabela26[[#This Row],[Gols 1T Contra]] -> 0 | AG3: =IF(AND(Tabela26[[#This Row],[Gols Pró]]>0.5,Tabela26[[#This Row],[Gols Contra]]>0.5),"Sim","Não") -> Não | AH3: =COUNTIFS(Tabela15[Time],Tabela26[[#This Row],[Time]],Tabela15[Aderência ao alvo (%)],">="&0.65,Tabela15[Favoritismo (preencher depois)],">="&Tabela26[[#This Row],[Favoristismo]]-0.2,Tabela15[Favoritismo (preencher depois)],"<="&Tabela26[[#This Row],[Favoristismo]]+0.2) -> 0 | AJ3: =B3&"|"&C3 -> |
O4: {=IFERROR(SUMPRODUCT((Times!$A$2:$A$61=$B4)*(Times!$AG$2:$AG$61>=65%)*(Times!$AH$2:$AH$61>=65%)*Times!$F$2:$F$61*Times!$AK$2:$AK$61)/SUMPRODUCT((Times!$A$2:$A$61=$B4)*(Times!$AG$2:$AG$61>=65%)*(Times!$AH$2:$AH$61>=65%)*Times!$AK$2:$AK$61),0)} -> 0 | P4: {=IFERROR(SUMPRODUCT((Times!$A$2:$A$61=$B4)*(Times!$AG$2:$AG$61>=65%)*(Times!$AH$2:$AH$61>=65%)*Times!$G$2:$G$61*Times!$AK$2:$AK$61)/SUMPRODUCT((Times!$A$2:$A$61=$B4)*(Times!$AG$2:$AG$61>=65%)*(Times!$AH$2:$AH$61>=65%)*Times!$AK$2:$AK$61),0)} -> 0 | Q4: =Tabela26[[#This Row],[Gols Pró]]+Tabela26[[#This Row],[Gols Contra]] -> 0 | R4: {=IFERROR(_xlfn.LET(_xlpm.tm,$B4,_xlpm.vals,_xlfn._xlws.FILTER(Times!$L$2:$L$61,Times!$A$2:$A$61=_xlpm.tm),_xlpm.ag,_xlfn._xlws.FILTER(Times!$AG$2:$AG$61,Times!$A$2:$A$61=_xlpm.tm),_xlpm.ah,_xlfn._xlws.FILTER(Times!$AH$2:$AH$61,Times!$A$2:$A$61=_xlpm.tm),_xlpm.ai,_xlfn._xlws.FILTER(Times!$AI$2:$AI$61,Times!$A$2:$A$61=_xlpm.tm),_xlpm.wt,_xlpm.ag*50%+_xlpm.ah*30%+_xlpm.ai*20%,_xlpm.n,ROWS(_xlpm.vals),_xlpm.avg,AVERAGE(_xlpm.vals),_xlpm.sd,IF(_xlpm.n>1,_xlfn.STDEV.S(_xlpm.vals),0),_xlpm.mask,IF(_xlpm.n<3,_xlfn.SEQUENCE(_xlpm.n,1,1,0)=1,ABS(_xlpm.vals-_xlpm.avg)<=_xlpm.sd)*(_xlpm.ag>=65%)*(_xlpm.ah>=65%),AVERAGE(_xlfn._xlws.FILTER(_xlpm.vals*_xlpm.wt,_xlpm.mask))),0)} -> 0 | S4: {=IFERROR(_xlfn.LET(_xlpm.tm,$B4,_xlpm.vals,_xlfn._xlws.FILTER(Times!$M$2:$M$61,Times!$A$2:$A$61=_xlpm.tm),_xlpm.ag,_xlfn._xlws.FILTER(Times!$AG$2:$AG$61,Times!$A$2:$A$61=_xlpm.tm),_xlpm.ah,_xlfn._xlws.FILTER(Times!$AH$2:$AH$61,Times!$A$2:$A$61=_xlpm.tm),_xlpm.ai,_xlfn._xlws.FILTER(Times!$AI$2:$AI$61,Times!$A$2:$A$61=_xlpm.tm),_xlpm.wt,_xlpm.ag*50%+_xlpm.ah*30%+_xlpm.ai*20%,_xlpm.n,ROWS(_xlpm.vals),_xlpm.avg,AVERAGE(_xlpm.vals),_xlpm.sd,IF(_xlpm.n>1,_xlfn.STDEV.S(_xlpm.vals),0),_xlpm.mask,IF(_xlpm.n<3,_xlfn.SEQUENCE(_xlpm.n,1,1,0)=1,ABS(_xlpm.vals-_xlpm.avg)<=_xlpm.sd)*(_xlpm.ag>=65%)*(_xlpm.ah>=65%),AVERAGE(_xlfn._xlws.FILTER(_xlpm.vals*_xlpm.wt,_xlpm.mask))),0)} -> 0 | T4: =Tabela26[[#This Row],[Cartões Pró]]+Tabela26[[#This Row],[Cartões Contra]] -> 0 | U4: {=IFERROR(_xlfn.LET(_xlpm.tm,$B4,_xlpm.vals,_xlfn._xlws.FILTER(Times!$J$2:$J$61,Times!$A$2:$A$61=_xlpm.tm),_xlpm.ag,_xlfn._xlws.FILTER(Times!$AG$2:$AG$61,Times!$A$2:$A$61=_xlpm.tm),_xlpm.ah,_xlfn._xlws.FILTER(Times!$AH$2:$AH$61,Times!$A$2:$A$61=_xlpm.tm),_xlpm.ai,_xlfn._xlws.FILTER(Times!$AI$2:$AI$61,Times!$A$2:$A$61=_xlpm.tm),_xlpm.wt,_xlpm.ag*50%+_xlpm.ah*30%+_xlpm.ai*20%,_xlpm.n,ROWS(_xlpm.vals),_xlpm.avg,AVERAGE(_xlpm.vals),_xlpm.sd,IF(_xlpm.n>1,_xlfn.STDEV.S(_xlpm.vals),0),_xlpm.mask,IF(_xlpm.n<3,_xlfn.SEQUENCE(_xlpm.n,1,1,0)=1,ABS(_xlpm.vals-_xlpm.avg)<=_xlpm.sd)*(_xlpm.ag>=65%)*(_xlpm.ah>=65%),AVERAGE(_xlfn._xlws.FILTER(_xlpm.vals*_xlpm.wt,_xlpm.mask))),0)} -> 0 | V4: {=IFERROR(_xlfn.LET(_xlpm.tm,$B4,_xlpm.vals,_xlfn._xlws.FILTER(Times!$K$2:$K$61,Times!$A$2:$A$61=_xlpm.tm),_xlpm.ag,_xlfn._xlws.FILTER(Times!$AG$2:$AG$61,Times!$A$2:$A$61=_xlpm.tm),_xlpm.ah,_xlfn._xlws.FILTER(Times!$AH$2:$AH$61,Times!$A$2:$A$61=_xlpm.tm),_xlpm.ai,_xlfn._xlws.FILTER(Times!$AI$2:$AI$61,Times!$A$2:$A$61=_xlpm.tm),_xlpm.wt,_xlpm.ag*50%+_xlpm.ah*30%+_xlpm.ai*20%,_xlpm.n,ROWS(_xlpm.vals),_xlpm.avg,AVERAGE(_xlpm.vals),_xlpm.sd,IF(_xlpm.n>1,_xlfn.STDEV.S(_xlpm.vals),0),_xlpm.mask,IF(_xlpm.n<3,_xlfn.SEQUENCE(_xlpm.n,1,1,0)=1,ABS(_xlpm.vals-_xlpm.avg)<=_xlpm.sd)*(_xlpm.ag>=65%)*(_xlpm.ah>=65%),AVERAGE(_xlfn._xlws.FILTER(_xlpm.vals*_xlpm.wt,_xlpm.mask))),0)} -> 0 | W4: =Tabela26[[#This Row],[Escanteios Pró]]+Tabela26[[#This Row],[Escanteios Contra]] -> 0 | X4: {=IFERROR(_xlfn.LET(_xlpm.tm,$B4,_xlpm.vals,_xlfn._xlws.FILTER(Times!$N$2:$N$61,Times!$A$2:$A$61=_xlpm.tm),_xlpm.ag,_xlfn._xlws.FILTER(Times!$AG$2:$AG$61,Times!$A$2:$A$61=_xlpm.tm),_xlpm.ah,_xlfn._xlws.FILTER(Times!$AH$2:$AH$61,Times!$A$2:$A$61=_xlpm.tm),_xlpm.ai,_xlfn._xlws.FILTER(Times!$AI$2:$AI$61,Times!$A$2:$A$61=_xlpm.tm),_xlpm.wt,_xlpm.ag*50%+_xlpm.ah*30%+_xlpm.ai*20%,_xlpm.n,ROWS(_xlpm.vals),_xlpm.avg,AVERAGE(_xlpm.vals),_xlpm.sd,IF(_xlpm.n>1,_xlfn.STDEV.S(_xlpm.vals),0),_xlpm.mask,IF(_xlpm.n<3,_xlfn.SEQUENCE(_xlpm.n,1,1,0)=1,ABS(_xlpm.vals-_xlpm.avg)<=_xlpm.sd)*(_xlpm.ag>=65%)*(_xlpm.ah>=65%),AVERAGE(_xlfn._xlws.FILTER(_xlpm.vals*_xlpm.wt,_xlpm.mask))),0)} -> 0 | Y4: {=IFERROR(_xlfn.LET(_xlpm.tm,$B4,_xlpm.vals,_xlfn._xlws.FILTER(Times!$O$2:$O$61,Times!$A$2:$A$61=_xlpm.tm),_xlpm.ag,_xlfn._xlws.FILTER(Times!$AG$2:$AG$61,Times!$A$2:$A$61=_xlpm.tm),_xlpm.ah,_xlfn._xlws.FILTER(Times!$AH$2:$AH$61,Times!$A$2:$A$61=_xlpm.tm),_xlpm.ai,_xlfn._xlws.FILTER(Times!$AI$2:$AI$61,Times!$A$2:$A$61=_xlpm.tm),_xlpm.wt,_xlpm.ag*50%+_xlpm.ah*30%+_xlpm.ai*20%,_xlpm.n,ROWS(_xlpm.vals),_xlpm.avg,AVERAGE(_xlpm.vals),_xlpm.sd,IF(_xlpm.n>1,_xlfn.STDEV.S(_xlpm.vals),0),_xlpm.mask,IF(_xlpm.n<3,_xlfn.SEQUENCE(_xlpm.n,1,1,0)=1,ABS(_xlpm.vals-_xlpm.avg)<=_xlpm.sd)*(_xlpm.ag>=65%)*(_xlpm.ah>=65%),AVERAGE(_xlfn._xlws.FILTER(_xlpm.vals*_xlpm.wt,_xlpm.mask))),0)} -> 0 | Z4: =Tabela26[[#This Row],[Chutes Pró]]+Tabela26[[#This Row],[Chutes Contra]] -> 0 | AA4: {=IFERROR(_xlfn.LET(_xlpm.tm,$B4,_xlpm.vals,_xlfn._xlws.FILTER(Times!$P$2:$P$61,Times!$A$2:$A$61=_xlpm.tm),_xlpm.ag,_xlfn._xlws.FILTER(Times!$AG$2:$AG$61,Times!$A$2:$A$61=_xlpm.tm),_xlpm.ah,_xlfn._xlws.FILTER(Times!$AH$2:$AH$61,Times!$A$2:$A$61=_xlpm.tm),_xlpm.ai,_xlfn._xlws.FILTER(Times!$AI$2:$AI$61,Times!$A$2:$A$61=_xlpm.tm),_xlpm.wt,_xlpm.ag*50%+_xlpm.ah*30%+_xlpm.ai*20%,_xlpm.n,ROWS(_xlpm.vals),_xlpm.avg,AVERAGE(_xlpm.vals),_xlpm.sd,IF(_xlpm.n>1,_xlfn.STDEV.S(_xlpm.vals),0),_xlpm.mask,IF(_xlpm.n<3,_xlfn.SEQUENCE(_xlpm.n,1,1,0)=1,ABS(_xlpm.vals-_xlpm.avg)<=_xlpm.sd)*(_xlpm.ag>=65%)*(_xlpm.ah>=65%),AVERAGE(_xlfn._xlws.FILTER(_xlpm.vals*_xlpm.wt,_xlpm.mask))),0)} -> 0 | AB4: {=IFERROR(_xlfn.LET(_xlpm.tm,$B4,_xlpm.vals,_xlfn._xlws.FILTER(Times!$Q$2:$Q$61,Times!$A$2:$A$61=_xlpm.tm),_xlpm.ag,_xlfn._xlws.FILTER(Times!$AG$2:$AG$61,Times!$A$2:$A$61=_xlpm.tm),_xlpm.ah,_xlfn._xlws.FILTER(Times!$AH$2:$AH$61,Times!$A$2:$A$61=_xlpm.tm),_xlpm.ai,_xlfn._xlws.FILTER(Times!$AI$2:$AI$61,Times!$A$2:$A$61=_xlpm.tm),_xlpm.wt,_xlpm.ag*50%+_xlpm.ah*30%+_xlpm.ai*20%,_xlpm.n,ROWS(_xlpm.vals),_xlpm.avg,AVERAGE(_xlpm.vals),_xlpm.sd,IF(_xlpm.n>1,_xlfn.STDEV.S(_xlpm.vals),0),_xlpm.mask,IF(_xlpm.n<3,_xlfn.SEQUENCE(_xlpm.n,1,1,0)=1,ABS(_xlpm.vals-_xlpm.avg)<=_xlpm.sd)*(_xlpm.ag>=65%)*(_xlpm.ah>=65%),AVERAGE(_xlfn._xlws.FILTER(_xlpm.vals*_xlpm.wt,_xlpm.mask))),0)} -> 0 | AC4: =Tabela26[[#This Row],[Chutes Gol Pró]]+Tabela26[[#This Row],[Chutes Gol Contra]] -> 0 | AD4: {=IFERROR(_xlfn.LET(_xlpm.tm,$B4,_xlpm.vals,_xlfn._xlws.FILTER(Times!$U$2:$U$61,Times!$A$2:$A$61=_xlpm.tm),_xlpm.ag,_xlfn._xlws.FILTER(Times!$AG$2:$AG$61,Times!$A$2:$A$61=_xlpm.tm),_xlpm.ah,_xlfn._xlws.FILTER(Times!$AH$2:$AH$61,Times!$A$2:$A$61=_xlpm.tm),_xlpm.ai,_xlfn._xlws.FILTER(Times!$AI$2:$AI$61,Times!$A$2:$A$61=_xlpm.tm),_xlpm.wt,_xlpm.ag*50%+_xlpm.ah*30%+_xlpm.ai*20%,_xlpm.n,ROWS(_xlpm.vals),_xlpm.avg,AVERAGE(_xlpm.vals),_xlpm.sd,IF(_xlpm.n>1,_xlfn.STDEV.S(_xlpm.vals),0),_xlpm.mask,IF(_xlpm.n<3,_xlfn.SEQUENCE(_xlpm.n,1,1,0)=1,ABS(_xlpm.vals-_xlpm.avg)<=_xlpm.sd)*(_xlpm.ag>=65%)*(_xlpm.ah>=65%),AVERAGE(_xlfn._xlws.FILTER(_xlpm.vals*_xlpm.wt,_xlpm.mask))),0)} -> 0 | AE4: {=IFERROR(_xlfn.LET(_xlpm.tm,$B4,_xlpm.vals,_xlfn._xlws.FILTER(Times!$V$2:$V$61,Times!$A$2:$A$61=_xlpm.tm),_xlpm.ag,_xlfn._xlws.FILTER(Times!$AG$2:$AG$61,Times!$A$2:$A$61=_xlpm.tm),_xlpm.ah,_xlfn._xlws.FILTER(Times!$AH$2:$AH$61,Times!$A$2:$A$61=_xlpm.tm),_xlpm.ai,_xlfn._xlws.FILTER(Times!$AI$2:$AI$61,Times!$A$2:$A$61=_xlpm.tm),_xlpm.wt,_xlpm.ag*50%+_xlpm.ah*30%+_xlpm.ai*20%,_xlpm.n,ROWS(_xlpm.vals),_xlpm.avg,AVERAGE(_xlpm.vals),_xlpm.sd,IF(_xlpm.n>1,_xlfn.STDEV.S(_xlpm.vals),0),_xlpm.mask,IF(_xlpm.n<3,_xlfn.SEQUENCE(_xlpm.n,1,1,0)=1,ABS(_xlpm.vals-_xlpm.avg)<=_xlpm.sd)*(_xlpm.ag>=65%)*(_xlpm.ah>=65%),AVERAGE(_xlfn._xlws.FILTER(_xlpm.vals*_xlpm.wt,_xlpm.mask))),0)} -> 0 | AF4: =Tabela26[[#This Row],[Gols 1T Pró]]+Tabela26[[#This Row],[Gols 1T Contra]] -> 0 | AG4: =IF(AND(Tabela26[[#This Row],[Gols Pró]]>0.5,Tabela26[[#This Row],[Gols Contra]]>0.5),"Sim","Não") -> Não | AH4: =COUNTIFS(Tabela15[Time],Tabela26[[#This Row],[Time]],Tabela15[Aderência ao alvo (%)],">="&0.65,Tabela15[Favoritismo (preencher depois)],">="&Tabela26[[#This Row],[Favoristismo]]-0.2,Tabela15[Favoritismo (preencher depois)],"<="&Tabela26[[#This Row],[Favoristismo]]+0.2) -> 0 | AJ4: =B4&"|"&C4 -> |
O5: {=IFERROR(SUMPRODUCT((Times!$A$2:$A$61=$B5)*(Times!$AG$2:$AG$61>=65%)*(Times!$AH$2:$AH$61>=65%)*Times!$F$2:$F$61*Times!$AK$2:$AK$61)/SUMPRODUCT((Times!$A$2:$A$61=$B5)*(Times!$AG$2:$AG$61>=65%)*(Times!$AH$2:$AH$61>=65%)*Times!$AK$2:$AK$61),0)} -> 0 | P5: {=IFERROR(SUMPRODUCT((Times!$A$2:$A$61=$B5)*(Times!$AG$2:$AG$61>=65%)*(Times!$AH$2:$AH$61>=65%)*Times!$G$2:$G$61*Times!$AK$2:$AK$61)/SUMPRODUCT((Times!$A$2:$A$61=$B5)*(Times!$AG$2:$AG$61>=65%)*(Times!$AH$2:$AH$61>=65%)*Times!$AK$2:$AK$61),0)} -> 0 | Q5: =Tabela26[[#This Row],[Gols Pró]]+Tabela26[[#This Row],[Gols Contra]] -> 0 | R5: {=IFERROR(_xlfn.LET(_xlpm.tm,$B5,_xlpm.vals,_xlfn._xlws.FILTER(Times!$L$2:$L$61,Times!$A$2:$A$61=_xlpm.tm),_xlpm.ag,_xlfn._xlws.FILTER(Times!$AG$2:$AG$61,Times!$A$2:$A$61=_xlpm.tm),_xlpm.ah,_xlfn._xlws.FILTER(Times!$AH$2:$AH$61,Times!$A$2:$A$61=_xlpm.tm),_xlpm.ai,_xlfn._xlws.FILTER(Times!$AI$2:$AI$61,Times!$A$2:$A$61=_xlpm.tm),_xlpm.wt,_xlpm.ag*50%+_xlpm.ah*30%+_xlpm.ai*20%,_xlpm.n,ROWS(_xlpm.vals),_xlpm.avg,AVERAGE(_xlpm.vals),_xlpm.sd,IF(_xlpm.n>1,_xlfn.STDEV.S(_xlpm.vals),0),_xlpm.mask,IF(_xlpm.n<3,_xlfn.SEQUENCE(_xlpm.n,1,1,0)=1,ABS(_xlpm.vals-_xlpm.avg)<=_xlpm.sd)*(_xlpm.ag>=65%)*(_xlpm.ah>=65%),AVERAGE(_xlfn._xlws.FILTER(_xlpm.vals*_xlpm.wt,_xlpm.mask))),0)} -> 0 | S5: {=IFERROR(_xlfn.LET(_xlpm.tm,$B5,_xlpm.vals,_xlfn._xlws.FILTER(Times!$M$2:$M$61,Times!$A$2:$A$61=_xlpm.tm),_xlpm.ag,_xlfn._xlws.FILTER(Times!$AG$2:$AG$61,Times!$A$2:$A$61=_xlpm.tm),_xlpm.ah,_xlfn._xlws.FILTER(Times!$AH$2:$AH$61,Times!$A$2:$A$61=_xlpm.tm),_xlpm.ai,_xlfn._xlws.FILTER(Times!$AI$2:$AI$61,Times!$A$2:$A$61=_xlpm.tm),_xlpm.wt,_xlpm.ag*50%+_xlpm.ah*30%+_xlpm.ai*20%,_xlpm.n,ROWS(_xlpm.vals),_xlpm.avg,AVERAGE(_xlpm.vals),_xlpm.sd,IF(_xlpm.n>1,_xlfn.STDEV.S(_xlpm.vals),0),_xlpm.mask,IF(_xlpm.n<3,_xlfn.SEQUENCE(_xlpm.n,1,1,0)=1,ABS(_xlpm.vals-_xlpm.avg)<=_xlpm.sd)*(_xlpm.ag>=65%)*(_xlpm.ah>=65%),AVERAGE(_xlfn._xlws.FILTER(_xlpm.vals*_xlpm.wt,_xlpm.mask))),0)} -> 0 | T5: =Tabela26[[#This Row],[Cartões Pró]]+Tabela26[[#This Row],[Cartões Contra]] -> 0 | U5: {=IFERROR(_xlfn.LET(_xlpm.tm,$B5,_xlpm.vals,_xlfn._xlws.FILTER(Times!$J$2:$J$61,Times!$A$2:$A$61=_xlpm.tm),_xlpm.ag,_xlfn._xlws.FILTER(Times!$AG$2:$AG$61,Times!$A$2:$A$61=_xlpm.tm),_xlpm.ah,_xlfn._xlws.FILTER(Times!$AH$2:$AH$61,Times!$A$2:$A$61=_xlpm.tm),_xlpm.ai,_xlfn._xlws.FILTER(Times!$AI$2:$AI$61,Times!$A$2:$A$61=_xlpm.tm),_xlpm.wt,_xlpm.ag*50%+_xlpm.ah*30%+_xlpm.ai*20%,_xlpm.n,ROWS(_xlpm.vals),_xlpm.avg,AVERAGE(_xlpm.vals),_xlpm.sd,IF(_xlpm.n>1,_xlfn.STDEV.S(_xlpm.vals),0),_xlpm.mask,IF(_xlpm.n<3,_xlfn.SEQUENCE(_xlpm.n,1,1,0)=1,ABS(_xlpm.vals-_xlpm.avg)<=_xlpm.sd)*(_xlpm.ag>=65%)*(_xlpm.ah>=65%),AVERAGE(_xlfn._xlws.FILTER(_xlpm.vals*_xlpm.wt,_xlpm.mask))),0)} -> 0 | V5: {=IFERROR(_xlfn.LET(_xlpm.tm,$B5,_xlpm.vals,_xlfn._xlws.FILTER(Times!$K$2:$K$61,Times!$A$2:$A$61=_xlpm.tm),_xlpm.ag,_xlfn._xlws.FILTER(Times!$AG$2:$AG$61,Times!$A$2:$A$61=_xlpm.tm),_xlpm.ah,_xlfn._xlws.FILTER(Times!$AH$2:$AH$61,Times!$A$2:$A$61=_xlpm.tm),_xlpm.ai,_xlfn._xlws.FILTER(Times!$AI$2:$AI$61,Times!$A$2:$A$61=_xlpm.tm),_xlpm.wt,_xlpm.ag*50%+_xlpm.ah*30%+_xlpm.ai*20%,_xlpm.n,ROWS(_xlpm.vals),_xlpm.avg,AVERAGE(_xlpm.vals),_xlpm.sd,IF(_xlpm.n>1,_xlfn.STDEV.S(_xlpm.vals),0),_xlpm.mask,IF(_xlpm.n<3,_xlfn.SEQUENCE(_xlpm.n,1,1,0)=1,ABS(_xlpm.vals-_xlpm.avg)<=_xlpm.sd)*(_xlpm.ag>=65%)*(_xlpm.ah>=65%),AVERAGE(_xlfn._xlws.FILTER(_xlpm.vals*_xlpm.wt,_xlpm.mask))),0)} -> 0 | W5: =Tabela26[[#This Row],[Escanteios Pró]]+Tabela26[[#This Row],[Escanteios Contra]] -> 0 | X5: {=IFERROR(_xlfn.LET(_xlpm.tm,$B5,_xlpm.vals,_xlfn._xlws.FILTER(Times!$N$2:$N$61,Times!$A$2:$A$61=_xlpm.tm),_xlpm.ag,_xlfn._xlws.FILTER(Times!$AG$2:$AG$61,Times!$A$2:$A$61=_xlpm.tm),_xlpm.ah,_xlfn._xlws.FILTER(Times!$AH$2:$AH$61,Times!$A$2:$A$61=_xlpm.tm),_xlpm.ai,_xlfn._xlws.FILTER(Times!$AI$2:$AI$61,Times!$A$2:$A$61=_xlpm.tm),_xlpm.wt,_xlpm.ag*50%+_xlpm.ah*30%+_xlpm.ai*20%,_xlpm.n,ROWS(_xlpm.vals),_xlpm.avg,AVERAGE(_xlpm.vals),_xlpm.sd,IF(_xlpm.n>1,_xlfn.STDEV.S(_xlpm.vals),0),_xlpm.mask,IF(_xlpm.n<3,_xlfn.SEQUENCE(_xlpm.n,1,1,0)=1,ABS(_xlpm.vals-_xlpm.avg)<=_xlpm.sd)*(_xlpm.ag>=65%)*(_xlpm.ah>=65%),AVERAGE(_xlfn._xlws.FILTER(_xlpm.vals*_xlpm.wt,_xlpm.mask))),0)} -> 0 | Y5: {=IFERROR(_xlfn.LET(_xlpm.tm,$B5,_xlpm.vals,_xlfn._xlws.FILTER(Times!$O$2:$O$61,Times!$A$2:$A$61=_xlpm.tm),_xlpm.ag,_xlfn._xlws.FILTER(Times!$AG$2:$AG$61,Times!$A$2:$A$61=_xlpm.tm),_xlpm.ah,_xlfn._xlws.FILTER(Times!$AH$2:$AH$61,Times!$A$2:$A$61=_xlpm.tm),_xlpm.ai,_xlfn._xlws.FILTER(Times!$AI$2:$AI$61,Times!$A$2:$A$61=_xlpm.tm),_xlpm.wt,_xlpm.ag*50%+_xlpm.ah*30%+_xlpm.ai*20%,_xlpm.n,ROWS(_xlpm.vals),_xlpm.avg,AVERAGE(_xlpm.vals),_xlpm.sd,IF(_xlpm.n>1,_xlfn.STDEV.S(_xlpm.vals),0),_xlpm.mask,IF(_xlpm.n<3,_xlfn.SEQUENCE(_xlpm.n,1,1,0)=1,ABS(_xlpm.vals-_xlpm.avg)<=_xlpm.sd)*(_xlpm.ag>=65%)*(_xlpm.ah>=65%),AVERAGE(_xlfn._xlws.FILTER(_xlpm.vals*_xlpm.wt,_xlpm.mask))),0)} -> 0 | Z5: =Tabela26[[#This Row],[Chutes Pró]]+Tabela26[[#This Row],[Chutes Contra]] -> 0 | AA5: {=IFERROR(_xlfn.LET(_xlpm.tm,$B5,_xlpm.vals,_xlfn._xlws.FILTER(Times!$P$2:$P$61,Times!$A$2:$A$61=_xlpm.tm),_xlpm.ag,_xlfn._xlws.FILTER(Times!$AG$2:$AG$61,Times!$A$2:$A$61=_xlpm.tm),_xlpm.ah,_xlfn._xlws.FILTER(Times!$AH$2:$AH$61,Times!$A$2:$A$61=_xlpm.tm),_xlpm.ai,_xlfn._xlws.FILTER(Times!$AI$2:$AI$61,Times!$A$2:$A$61=_xlpm.tm),_xlpm.wt,_xlpm.ag*50%+_xlpm.ah*30%+_xlpm.ai*20%,_xlpm.n,ROWS(_xlpm.vals),_xlpm.avg,AVERAGE(_xlpm.vals),_xlpm.sd,IF(_xlpm.n>1,_xlfn.STDEV.S(_xlpm.vals),0),_xlpm.mask,IF(_xlpm.n<3,_xlfn.SEQUENCE(_xlpm.n,1,1,0)=1,ABS(_xlpm.vals-_xlpm.avg)<=_xlpm.sd)*(_xlpm.ag>=65%)*(_xlpm.ah>=65%),AVERAGE(_xlfn._xlws.FILTER(_xlpm.vals*_xlpm.wt,_xlpm.mask))),0)} -> 0 | AB5: {=IFERROR(_xlfn.LET(_xlpm.tm,$B5,_xlpm.vals,_xlfn._xlws.FILTER(Times!$Q$2:$Q$61,Times!$A$2:$A$61=_xlpm.tm),_xlpm.ag,_xlfn._xlws.FILTER(Times!$AG$2:$AG$61,Times!$A$2:$A$61=_xlpm.tm),_xlpm.ah,_xlfn._xlws.FILTER(Times!$AH$2:$AH$61,Times!$A$2:$A$61=_xlpm.tm),_xlpm.ai,_xlfn._xlws.FILTER(Times!$AI$2:$AI$61,Times!$A$2:$A$61=_xlpm.tm),_xlpm.wt,_xlpm.ag*50%+_xlpm.ah*30%+_xlpm.ai*20%,_xlpm.n,ROWS(_xlpm.vals),_xlpm.avg,AVERAGE(_xlpm.vals),_xlpm.sd,IF(_xlpm.n>1,_xlfn.STDEV.S(_xlpm.vals),0),_xlpm.mask,IF(_xlpm.n<3,_xlfn.SEQUENCE(_xlpm.n,1,1,0)=1,ABS(_xlpm.vals-_xlpm.avg)<=_xlpm.sd)*(_xlpm.ag>=65%)*(_xlpm.ah>=65%),AVERAGE(_xlfn._xlws.FILTER(_xlpm.vals*_xlpm.wt,_xlpm.mask))),0)} -> 0 | AC5: =Tabela26[[#This Row],[Chutes Gol Pró]]+Tabela26[[#This Row],[Chutes Gol Contra]] -> 0 | AD5: {=IFERROR(_xlfn.LET(_xlpm.tm,$B5,_xlpm.vals,_xlfn._xlws.FILTER(Times!$U$2:$U$61,Times!$A$2:$A$61=_xlpm.tm),_xlpm.ag,_xlfn._xlws.FILTER(Times!$AG$2:$AG$61,Times!$A$2:$A$61=_xlpm.tm),_xlpm.ah,_xlfn._xlws.FILTER(Times!$AH$2:$AH$61,Times!$A$2:$A$61=_xlpm.tm),_xlpm.ai,_xlfn._xlws.FILTER(Times!$AI$2:$AI$61,Times!$A$2:$A$61=_xlpm.tm),_xlpm.wt,_xlpm.ag*50%+_xlpm.ah*30%+_xlpm.ai*20%,_xlpm.n,ROWS(_xlpm.vals),_xlpm.avg,AVERAGE(_xlpm.vals),_xlpm.sd,IF(_xlpm.n>1,_xlfn.STDEV.S(_xlpm.vals),0),_xlpm.mask,IF(_xlpm.n<3,_xlfn.SEQUENCE(_xlpm.n,1,1,0)=1,ABS(_xlpm.vals-_xlpm.avg)<=_xlpm.sd)*(_xlpm.ag>=65%)*(_xlpm.ah>=65%),AVERAGE(_xlfn._xlws.FILTER(_xlpm.vals*_xlpm.wt,_xlpm.mask))),0)} -> 0 | AE5: {=IFERROR(_xlfn.LET(_xlpm.tm,$B5,_xlpm.vals,_xlfn._xlws.FILTER(Times!$V$2:$V$61,Times!$A$2:$A$61=_xlpm.tm),_xlpm.ag,_xlfn._xlws.FILTER(Times!$AG$2:$AG$61,Times!$A$2:$A$61=_xlpm.tm),_xlpm.ah,_xlfn._xlws.FILTER(Times!$AH$2:$AH$61,Times!$A$2:$A$61=_xlpm.tm),_xlpm.ai,_xlfn._xlws.FILTER(Times!$AI$2:$AI$61,Times!$A$2:$A$61=_xlpm.tm),_xlpm.wt,_xlpm.ag*50%+_xlpm.ah*30%+_xlpm.ai*20%,_xlpm.n,ROWS(_xlpm.vals),_xlpm.avg,AVERAGE(_xlpm.vals),_xlpm.sd,IF(_xlpm.n>1,_xlfn.STDEV.S(_xlpm.vals),0),_xlpm.mask,IF(_xlpm.n<3,_xlfn.SEQUENCE(_xlpm.n,1,1,0)=1,ABS(_xlpm.vals-_xlpm.avg)<=_xlpm.sd)*(_xlpm.ag>=65%)*(_xlpm.ah>=65%),AVERAGE(_xlfn._xlws.FILTER(_xlpm.vals*_xlpm.wt,_xlpm.mask))),0)} -> 0 | AF5: =Tabela26[[#This Row],[Gols 1T Pró]]+Tabela26[[#This Row],[Gols 1T Contra]] -> 0 | AG5: =IF(AND(Tabela26[[#This Row],[Gols Pró]]>0.5,Tabela26[[#This Row],[Gols Contra]]>0.5),"Sim","Não") -> Não | AH5: =COUNTIFS(Tabela15[Time],Tabela26[[#This Row],[Time]],Tabela15[Aderência ao alvo (%)],">="&0.65,Tabela15[Favoritismo (preencher depois)],">="&Tabela26[[#This Row],[Favoristismo]]-0.2,Tabela15[Favoritismo (preencher depois)],"<="&Tabela26[[#This Row],[Favoristismo]]+0.2) -> 0 | AJ5: =B5&"|"&C5 -> |

Sheet Mercados
A1: Jogo | B1: Mercado | C1: Tipo | D1: Critério 1 | E1: Critério 2 | F1: P.Plan | G1: P.Font | H1: P.Mkt | I1: P.Comb | J1: Odd Gatilho | K1: Odd Mercado | L1: Edge | M1: Veredito | N1: Odd Betano | O1: Veredito Betano | P1: Stake | Q1: Critérios | R1: TimeA | S1: TimeB | T1: λ_A | U1: λ_B
F2: {=IFERROR(_xlfn.LET(_xlpm.critOne,D2,_xlpm.critTwo,E2,_xlpm.la,MAX(0,T2),_xlpm.lb,MAX(0,U2),_xlpm.g,_xlfn.SEQUENCE(21,,0),_xlpm.x,_xlpm.g,_xlpm.y,TRANSPOSE(_xlpm.g),_xlpm.p,_xlfn.POISSON.DIST(_xlpm.x,_xlpm.la,FALSE)*_xlfn.POISSON.DIST(_xlpm.y,_xlpm.lb,FALSE),_xlpm.rawOne,TRIM(IFERROR(_xlfn.TEXTBEFORE(_xlpm.critOne,"|"),_xlpm.critOne)),_xlpm.rawTwo,TRIM(IFERROR(_xlfn.TEXTBEFORE(_xlpm.critTwo,"|"),_xlpm.critTwo)),_xlpm.multOne,IFERROR(_xlfn.NUMBERVALUE(TRIM(_xlfn.TEXTAFTER(_xlpm.critOne,"|")),".",","),1),_xlpm.multTwo,IFERROR(_xlfn.NUMBERVALUE(TRIM(_xlfn.TEXTAFTER(_xlpm.critTwo,"|")),".",","),1),_xlpm.lineOne,IFERROR(_xlfn.NUMBERVALUE(_xlfn.TEXTBEFORE(_xlfn.TEXTAFTER(_xlpm.rawOne," ")&" "," "),".",","),0),_xlpm.lineTwo,IFERROR(_xlfn.NUMBERVALUE(_xlfn.TEXTBEFORE(_xlfn.TEXTAFTER(_xlpm.rawTwo," ")&" "," "),".",","),0),_xlpm.handOne,IFERROR(_xlfn.NUMBERVALUE(_xlfn.TEXTAFTER(_xlpm.rawOne,"AH "),".",","),0),_xlpm.handTwo,IFERROR(_xlfn.NUMBERVALUE(_xlfn.TEXTAFTER(_xlpm.rawTwo,"AH "),".",","),0),_xlpm.lambdaFt,(_xlpm.la+_xlpm.lb)*0.42,_xlpm.condOne,IF(_xlpm.rawOne="",1,IF(_xlpm.rawOne="BTTS Sim",--((_xlpm.x>0)*(_xlpm.y>0)),IF(_xlpm.rawOne="BTTS Não",--(((_xlpm.x=0)+(_xlpm.y=0))>0),IF(ISNUMBER(SEARCH(" 1T",_xlpm.rawOne)),IF(LEFT(_xlpm.rawOne,4)="Over",1-_xlfn.POISSON.DIST(INT(_xlpm.lineOne),_xlpm.lambdaFt,TRUE),_xlfn.POISSON.DIST(INT(_xlpm.lineOne),_xlpm.lambdaFt,TRUE)),IF(LEFT(_xlpm.rawOne,4)="Over",--((_xlpm.x+_xlpm.y)>_xlpm.lineOne),IF(LEFT(_xlpm.rawOne,5)="Under",--((_xlpm.x+_xlpm.y)<_xlpm.lineOne),IF(_xlpm.rawOne="TimeA vence",--(_xlpm.x>_xlpm.y),IF(_xlpm.rawOne="TimeB vence",--(_xlpm.y>_xlpm.x),IF(_xlpm.rawOne="Empate",--(_xlpm.x=_xlpm.y),IF(_xlpm.rawOne="TimeA DC",--(_xlpm.x>=_xlpm.y),IF(_xlpm.rawOne="TimeB DC",--(_xlpm.y>=_xlpm.x),IF(ISNUMBER(SEARCH("TimeA AH",_xlpm.rawOne)),--(_xlpm.x+_xlpm.handOne>_xlpm.y),IF(ISNUMBER(SEARCH("TimeB AH",_xlpm.rawOne)),--(_xlpm.y+_xlpm.handOne>_xlpm.x),1))))))))))))),_xlpm.condTwo,IF(_xlpm.rawTwo="",1,IF(_xlpm.rawTwo="BTTS Sim",--((_xlpm.x>0)*(_xlpm.y>0)),IF(_xlpm.rawTwo="BTTS Não",--(((_xlpm.x=0)+(_xlpm.y=0))>0),IF(ISNUMBER(SEARCH(" 1T",_xlpm.rawTwo)),IF(LEFT(_xlpm.rawTwo,4)="Over",1-_xlfn.POISSON.DIST(INT(_xlpm.lineTwo),_xlpm.lambdaFt,TRUE),_xlfn.POISSON.DIST(INT(_xlpm.lineTwo),_xlpm.lambdaFt,TRUE)),IF(LEFT(_xlpm.rawTwo,4)="Over",--((_xlpm.x+_xlpm.y)>_xlpm.lineTwo),IF(LEFT(_xlpm.rawTwo,5)="Under",--((_xlpm.x+_xlpm.y)<_xlpm.lineTwo),IF(_xlpm.rawTwo="TimeA vence",--(_xlpm.x>_xlpm.y),IF(_xlpm.rawTwo="TimeB vence",--(_xlpm.y>_xlpm.x),IF(_xlpm.rawTwo="Empate",--(_xlpm.x=_xlpm.y),IF(_xlpm.rawTwo="TimeA DC",--(_xlpm.x>=_xlpm.y),IF(_xlpm.rawTwo="TimeB DC",--(_xlpm.y>=_xlpm.x),IF(ISNUMBER(SEARCH("TimeA AH",_xlpm.rawTwo)),--(_xlpm.x+_xlpm.handTwo>_xlpm.y),IF(ISNUMBER(SEARCH("TimeB AH",_xlpm.rawTwo)),--(_xlpm.y+_xlpm.handTwo>_xlpm.x),1))))))))))))),SUM(_xlpm.p*_xlpm.condOne*_xlpm.condTwo)*_xlpm.multOne*_xlpm.multTwo),0)} -> 1 | H2: =1/Tabela37[[#This Row],[Odd Mercado]] -> #DIV/0! | I2: =(Tabela37[[#This Row],[P.Plan]]*0.45)+(Tabela37[[#This Row],[P.Font]]*0.55) -> 0.45 | J2: =1/Tabela37[[#This Row],[P.Comb]] -> 2.2222222 | L2: =(Tabela37[[#This Row],[Odd Mercado]]/Tabela37[[#This Row],[Odd Gatilho]])-1 -> -1 | M2: =IF(AND(I2>60%,L2>=-15%,L2<=15%),"⭐Conferir",IF(L2>15%,"✅✅ Forte Valor",IF(L2>10%,"✅ Entra",IF(L2>=0%,"🟡 Borderline",IF(L2<-15%,"🔴 Evitar","❌ Sem valor"))))) -> 🔴 Evitar | O2: =IF(N2="","— digite a odd —",IF(N2>=1.1/(1.1/Tabela37[[#This Row],[Odd Gatilho]]),"✅ ENTRA (edge "&TEXT(N2*(1.1/Tabela37[[#This Row],[Odd Gatilho]])-1,"0%")&")",IF(N2>=1/(1.1/Tabela37[[#This Row],[Odd Gatilho]]),"🟡 break-even (edge "&TEXT(N2*(1.1/Tabela37[[#This Row],[Odd Gatilho]])-1,"0%")&")","❌ sem valor"))) -> — digite a odd — | P2: =IF(OR(N2="",N2<=1),"",IF(N2<1/0.483,0,ROUND(MIN(3,MAX(0.5,0.25*((N2*0.483-1)/(N2-1))*10)),1))) | Q2: =IF(AND(--Tabela37[[#This Row],[P.Plan]]>--Tabela37[[#This Row],[P.Font]],--Tabela37[[#This Row],[P.Font]]>=--Tabela37[[#This Row],[P.Mkt]],--Tabela37[[#This Row],[P.Mkt]]>=60%),"🎯 Edge Real", IF(AND(--Tabela37[[#This Row],[P.Font]]>=--Tabela37[[#This Row],[P.Mkt]],--Tabela37[[#This Row],[P.Mkt]]>=60%),"📡 Sinal Externo", IF(AND(--Tabela37[[#This Row],[P.Comb]]>=65%,--Tabela37[[#This Row],[Odd Mercado]]<=1.8),"✅ Alta Certeza", IF(AND(--Tabela37[[#This Row],[P.Comb]]>=55%,--Tabela37[[#This Row],[Edge]]>0.1),"📊 Referência","❌ Sem critério")))) -> #DIV/0! | R2: =SUBSTITUTE(TRIM(LEFT(A2,FIND(" x ",A2)-1)),"USA","USMNT") -> #VALUE! | S2: =SUBSTITUTE(TRIM(MID(A2,FIND(" x ",A2)+3,100)),"USA","USMNT") -> #VALUE! | T2: =IFERROR(AVERAGE(INDEX('Jogos do Dia'!$O$2:$O$5,MATCH(R2&"|"&S2,'Jogos do Dia'!$AJ$2:$AJ$5,0)),INDEX('Jogos do Dia'!$P$2:$P$5,MATCH(S2&"|"&R2,'Jogos do Dia'!$AJ$2:$AJ$5,0))),1.2) -> 1.2 | U2: =IFERROR(AVERAGE(INDEX('Jogos do Dia'!$O$2:$O$5,MATCH(S2&"|"&R2,'Jogos do Dia'!$AJ$2:$AJ$5,0)),INDEX('Jogos do Dia'!$P$2:$P$5,MATCH(R2&"|"&S2,'Jogos do Dia'!$AJ$2:$AJ$5,0))),1.2) -> 1.2
